Workbook

Sheet 收支紀錄
A1: 時間戳記 | B1: 類別 | C1: 金額(NTD) | D1: 日期(其他請填yyyymmdd, ex:20240808) | E1: 收入主分類 | F1: 工作選項 | G1: 其他業外選項 | H1: 支出主分類 | I1: 食品酒水選項 | J1: 日常生活選項 | K1: 房屋支出選項 | L1: 行車交通選項 | M1: 休閒娛樂選項 | N1: 稅金保險選項 | O1: 醫療費用選項 | P1: 進修學習選項 | Q1: 人情往來 | R1: 其他投資選項 | S1: 備註 | T1: 是否紀錄於總表?
A2: 45487.513 | B2: 支出 | C2: 82 | D2: 45487 | H2: 行車交通 | L2: 火車費
A3: 45487.513 | B3: 支出 | C3: 148 | D3: 45487 | H3: 行車交通 | L3: 加油
A4: 45487.514 | B4: 支出 | C4: 100 | D4: 45487 | H4: 休閒娛樂 | M4: 運動健身
A5: 45487.514 | B5: 支出 | C5: 60 | D5: 45487 | H5: 日常生活 | J5: 日常用品
A6: 45487.514 | B6: 支出 | C6: 77 | D6: 45487 | H6: 行車交通 | L6: 火車費
A7: 45487.514 | B7: 支出 | C7: 380 | D7: 45487 | H7: 食品酒水 | I7: 早餐
A8: 45487.515 | B8: 支出 | C8: 510 | D8: 45487 | H8: 食品酒水 | I8: 晚餐
A9: 45487.515 | B9: 支出 | C9: 359 | D9: 45487 | H9: 日常生活 | J9: 日常用品
A10: 45487.515 | B10: 支出 | C10: 233 | D10: 45487 | H10: 日常生活 | J10: 日常用品
A11: 45487.515 | B11: 支出 | C11: 20 | D11: 45487 | H11: 行車交通 | L11: 停車
A12: 45487.515 | B12: 支出 | C12: 78 | D12: 45487 | H12: 食品酒水 | I12: 早餐
A13: 45487.515 | B13: 支出 | C13: 515 | D13: 45487 | H13: 休閒娛樂 | M13: 公司福利金
A14: 45487.516 | B14: 支出 | C14: 1303 | D14: 45487 | H14: 食品酒水 | I14: 前月公司餐費扣款
A15: 45487.516 | B15: 支出 | C15: 180 | D15: 45487 | H15: 休閒娛樂 | M15: 運動健身
A16: 45487.516 | B16: 支出 | C16: 520 | D16: 45487 | H16: 食品酒水 | I16: 晚餐
A17: 45487.516 | B17: 支出 | C17: 211 | D17: 45487 | H17: 食品酒水 | I17: 食材
A18: 45487.516 | B18: 支出 | C18: 50 | D18: 45487 | H18: 食品酒水 | I18: 宵夜
A19: 45487.517 | B19: 支出 | C19: 100 | D19: 45487 | H19: 休閒娛樂 | M19: 運動健身
A20: 45487.517 | B20: 支出 | C20: 930 | D20: 45487 | H20: 行車交通 | L20: 高鐵
A21: 45487.517 | B21: 支出 | C21: 205 | D21: 45487 | H21: 食品酒水 | I21: 晚餐
A22: 45487.517 | B22: 支出 | C22: 99 | D22: 45487 | H22: 食品酒水 | I22: 宵夜
A23: 45487.517 | B23: 支出 | C23: 379 | D23: 45487 | H23: 食品酒水 | I23: 晚餐
A24: 45487.518 | B24: 支出 | C24: 45 | D24: 45487 | H24: 行車交通 | L24: 停車
A25: 45487.518 | B25: 支出 | C25: 798 | D25: 45487 | H25: 休閒娛樂 | M25: youtube Premium
A26: 45487.518 | B26: 支出 | C26: 391 | D26: 45487 | H26: 食品酒水 | I26: 晚餐
A27: 45487.518 | B27: 支出 | C27: 50 | D27: 45487 | H27: 行車交通 | L27: 停車
A28: 45487.518 | B28: 支出 | C28: 250 | D28: 45487 | H28: 食品酒水 | I28: 宵夜
A29: 45487.519 | B29: 支出 | C29: 460 | D29: 45487 | H29: 行車交通 | L29: 火車費
A30: 45487.91 | B30: 支出 | C30: 1118 | D30: 45487 | H30: 食品酒水 | I30: 食材
A31: 45488.35 | B31: 支出 | C31: 82 | D31: 45488 | H31: 行車交通 | L31: 火車費
A32: 45490.002 | B32: 收入 | C32: 930 | D32: 45489 | E32: 其他業外 | G32: 股票配息 | S32: 00751B | T32: 是
A33: 45491.968 | B33: 支出 | C33: 100 | D33: 45490 | H33: 休閒娛樂 | M33: 運動健身
A34: 45491.969 | B34: 支出 | C34: 23 | D34: 45490 | H34: 食品酒水 | I34: 飲料酒水
A35: 45493.357 | B35: 支出 | C35: 145 | D35: 45493 | H35: 食品酒水 | I35: 早餐
A36: 45493.406 | B36: 支出 | C36: 48 | D36: 45493 | H36: 食品酒水 | I36: 食材
A37: 45494.34 | B37: 支出 | C37: 58 | D37: 45494 | H37: 食品酒水 | I37: 早餐
A38: 45494.886 | B38: 支出 | C38: 200 | D38: 45494 | H38: 食品酒水 | I38: 午餐
A39: 45494.887 | B39: 支出 | C39: 140 | D39: 45494 | H39: 休閒娛樂 | M39: 運動健身
A40: 45494.887 | B40: 支出 | C40: 400 | D40: 45494 | H40: 食品酒水 | I40: 食材
...

Sheet Calculation
B1: 工作 | F1: 其他業外
A2: 收入 | B2: 底薪 | C2: 加班/津貼 | D2: 年終/績效 | E2: 備註 | F2: 股票配息 | G2: 發票/彩券/中獎 | H2: 保險理賠 | I2: 租金 | J2: 房屋補貼 | K2: 其他 | L2: 備註
A3: 45474 | B3: =SUMIFS(INDIRECT("C"&$C$70&":C"), INDIRECT("B"&$C$70&":B"), ">="&$A3, INDIRECT("B"&$C$70&":B"), "<"&$A4, INDIRECT("F"&$C$70&":F"), B$2) -> 102900 | C3: =SUMIFS(INDIRECT("C"&$C$70&":C"), INDIRECT("B"&$C$70&":B"), ">="&$A3, INDIRECT("B"&$C$70&":B"), "<"&$A4, INDIRECT("F"&$C$70&":F"), C$2) -> 22150 | D3: =SUMIFS(INDIRECT("C"&$C$70&":C"), INDIRECT("B"&$C$70&":B"), ">="&$A3, INDIRECT("B"&$C$70&":B"), "<"&$A4, INDIRECT("F"&$C$70&":F"), D$2) -> 100000 | E3: =IFERROR(__xludf.DUMMYFUNCTION("TEXTJOIN("", "", TRUE, FILTER(INDIRECT(""U""&$C$70&"":U""), INDIRECT(""E""&$C$70&"":E"") = $B$1, INDIRECT(""B""&$C$70&"":B"") >= $A3, INDIRECT(""B""&$C$70&"":B"") <$A4))"),"$17150特休折現, $5000體檢補助, $100000七月獎金") -> $17150特休折現, $5000體檢補助, $100000七月獎金 | F3: =SUMIFS(INDIRECT("C"&$C$70&":C"), INDIRECT("B"&$C$70&":B"), ">="&$A3, INDIRECT("B"&$C$70&":B"), "<"&$A4, INDIRECT("G"&$C$70&":G"), F$2) -> 9466 | G3: =SUMIFS(INDIRECT("C"&$C$70&":C"), INDIRECT("B"&$C$70&":B"), ">="&$A3, INDIRECT("B"&$C$70&":B"), "<"&$A4, INDIRECT("G"&$C$70&":G"), G$2) -> 0 | H3: =SUMIFS(INDIRECT("C"&$C$70&":C"), INDIRECT("B"&$C$70&":B"), ">="&$A3, INDIRECT("B"&$C$70&":B"), "<"&$A4, INDIRECT("G"&$C$70&":G"), H$2) -> 0 | I3: =SUMIFS(INDIRECT("C"&$C$70&":C"), INDIRECT("B"&$C$70&":B"), ">="&$A3, INDIRECT("B"&$C$70&":B"), "<"&$A4, INDIRECT("G"&$C$70&":G"), I$2) -> 0 | J3: =SUMIFS(INDIRECT("C"&$C$70&":C"), INDIRECT("B"&$C$70&":B"), ">="&$A3, INDIRECT("B"&$C$70&":B"), "<"&$A4, INDIRECT("G"&$C$70&":G"), J$2) -> 0 | K3: =SUMIFS(INDIRECT("C"&$C$70&":C"), INDIRECT("B"&$C$70&":B"), ">="&$A3, INDIRECT("B"&$C$70&":B"), "<"&$A4, INDIRECT("G"&$C$70&":G"), K$2) -> 0 | L3: =IFERROR(__xludf.DUMMYFUNCTION("TEXTJOIN("", "", TRUE, FILTER(INDIRECT(""U""&$C$70&"":U""), INDIRECT(""E""&$C$70&"":E"") = $F$1, INDIRECT(""B""&$C$70&"":B"") >= $A3, INDIRECT(""B""&$C$70&"":B"") <$A4))"),"$930 00751B, $1185元大金, $1990國泰金, $990台泥, $1491開發金, $1490正隆, $1390中再保") -> $930 00751B, $1185元大金, $1990國泰金, $990台泥, $1491開發金, $1490正隆, $1390中再保
A4: 45505 | B4: =SUMIFS(INDIRECT("C"&$C$70&":C"), INDIRECT("B"&$C$70&":B"), ">="&$A4, INDIRECT("B"&$C$70&":B"), "<"&$A5, INDIRECT("F"&$C$70&":F"), B$2) -> 102900 | C4: =SUMIFS(INDIRECT("C"&$C$70&":C"), INDIRECT("B"&$C$70&":B"), ">="&$A4, INDIRECT("B"&$C$70&":B"), "<"&$A5, INDIRECT("F"&$C$70&":F"), C$2) -> 1000 | D4: =SUMIFS(INDIRECT("C"&$C$70&":C"), INDIRECT("B"&$C$70&":B"), ">="&$A4, INDIRECT("B"&$C$70&":B"), "<"&$A5, INDIRECT("F"&$C$70&":F"), D$2) -> 0 | E4: =IFERROR(__xludf.DUMMYFUNCTION("TEXTJOIN("", "", TRUE, FILTER(INDIRECT(""U""&$C$70&"":U""), INDIRECT(""E""&$C$70&"":E"") = $B$1, INDIRECT(""B""&$C$70&"":B"") >= $A4, INDIRECT(""B""&$C$70&"":B"") <$A5))"),"$1000生日禮金") -> $1000生日禮金 | F4: =SUMIFS(INDIRECT("C"&$C$70&":C"), INDIRECT("B"&$C$70&":B"), ">="&$A4, INDIRECT("B"&$C$70&":B"), "<"&$A5, INDIRECT("G"&$C$70&":G"), F$2) -> 13981 | G4: =SUMIFS(INDIRECT("C"&$C$70&":C"), INDIRECT("B"&$C$70&":B"), ">="&$A4, INDIRECT("B"&$C$70&":B"), "<"&$A5, INDIRECT("G"&$C$70&":G"), G$2) -> 200 | H4: =SUMIFS(INDIRECT("C"&$C$70&":C"), INDIRECT("B"&$C$70&":B"), ">="&$A4, INDIRECT("B"&$C$70&":B"), "<"&$A5, INDIRECT("G"&$C$70&":G"), H$2) -> 0 | I4: =SUMIFS(INDIRECT("C"&$C$70&":C"), INDIRECT("B"&$C$70&":B"), ">="&$A4, INDIRECT("B"&$C$70&":B"), "<"&$A5, INDIRECT("G"&$C$70&":G"), I$2) -> 0 | J4: =SUMIFS(INDIRECT("C"&$C$70&":C"), INDIRECT("B"&$C$70&":B"), ">="&$A4, INDIRECT("B"&$C$70&":B"), "<"&$A5, INDIRECT("G"&$C$70&":G"), J$2) -> 0 | K4: =SUMIFS(INDIRECT("C"&$C$70&":C"), INDIRECT("B"&$C$70&":B"), ">="&$A4, INDIRECT("B"&$C$70&":B"), "<"&$A5, INDIRECT("G"&$C$70&":G"), K$2) -> 172 | L4: =IFERROR(__xludf.DUMMYFUNCTION("TEXTJOIN("", "", TRUE, FILTER(INDIRECT(""U""&$C$70&"":U""), INDIRECT(""E""&$C$70&"":E"") = $F$1, INDIRECT(""B""&$C$70&"":B"") >= $A4, INDIRECT(""B""&$C$70&"":B"") <$A5))"),"$172禾聯碩出借, $1190皇鼎, $200發票, $850山隆, $2090亞泥, $390聯邦銀, $693中鋼, $973台中銀行, $1846第一金, $1642玉山金, $1845台新金, $2462華南金") -> $172禾聯碩出借, $1190皇鼎, $200發票, $850山隆, $2090亞泥, $390聯邦銀, $693中鋼, $973台中銀行, $1846第一金, $1642玉山金, $1845台新金, $2462華南金
A5: 45536 | B5: =SUMIFS(INDIRECT("C"&$C$70&":C"), INDIRECT("B"&$C$70&":B"), ">="&$A5, INDIRECT("B"&$C$70&":B"), "<"&$A6, INDIRECT("F"&$C$70&":F"), B$2) -> 102900 | C5: =SUMIFS(INDIRECT("C"&$C$70&":C"), INDIRECT("B"&$C$70&":B"), ">="&$A5, INDIRECT("B"&$C$70&":B"), "<"&$A6, INDIRECT("F"&$C$70&":F"), C$2) -> 1000 | D5: =SUMIFS(INDIRECT("C"&$C$70&":C"), INDIRECT("B"&$C$70&":B"), ">="&$A5, INDIRECT("B"&$C$70&":B"), "<"&$A6, INDIRECT("F"&$C$70&":F"), D$2) -> 0 | E5: =IFERROR(__xludf.DUMMYFUNCTION("TEXTJOIN("", "", TRUE, FILTER(INDIRECT(""U""&$C$70&"":U""), INDIRECT(""E""&$C$70&"":E"") = $B$1, INDIRECT(""B""&$C$70&"":B"") >= $A5, INDIRECT(""B""&$C$70&"":B"") <$A6))"),"$1000中秋獎金") -> $1000中秋獎金 | F5: =SUMIFS(INDIRECT("C"&$C$70&":C"), INDIRECT("B"&$C$70&":B"), ">="&$A5, INDIRECT("B"&$C$70&":B"), "<"&$A6, INDIRECT("G"&$C$70&":G"), F$2) -> 16544 | G5: =SUMIFS(INDIRECT("C"&$C$70&":C"), INDIRECT("B"&$C$70&":B"), ">="&$A5, INDIRECT("B"&$C$70&":B"), "<"&$A6, INDIRECT("G"&$C$70&":G"), G$2) -> 0 | H5: =SUMIFS(INDIRECT("C"&$C$70&":C"), INDIRECT("B"&$C$70&":B"), ">="&$A5, INDIRECT("B"&$C$70&":B"), "<"&$A6, INDIRECT("G"&$C$70&":G"), H$2) -> 0 | I5: =SUMIFS(INDIRECT("C"&$C$70&":C"), INDIRECT("B"&$C$70&":B"), ">="&$A5, INDIRECT("B"&$C$70&":B"), "<"&$A6, INDIRECT("G"&$C$70&":G"), I$2) -> 0 | J5: =SUMIFS(INDIRECT("C"&$C$70&":C"), INDIRECT("B"&$C$70&":B"), ">="&$A5, INDIRECT("B"&$C$70&":B"), "<"&$A6, INDIRECT("G"&$C$70&":G"), J$2) -> 0 | K5: =SUMIFS(INDIRECT("C"&$C$70&":C"), INDIRECT("B"&$C$70&":B"), ">="&$A5, INDIRECT("B"&$C$70&":B"), "<"&$A6, INDIRECT("G"&$C$70&":G"), K$2) -> 0 | L5: =IFERROR(__xludf.DUMMYFUNCTION("TEXTJOIN("", "", TRUE, FILTER(INDIRECT(""U""&$C$70&"":U""), INDIRECT(""E""&$C$70&"":E"") = $F$1, INDIRECT(""B""&$C$70&"":B"") >= $A5, INDIRECT(""B""&$C$70&"":B"") <$A6))"),"$3440元大美債, $2291台企銀, $1653兆豐金, $2590合庫金, $890高雄銀, $1690彰銀, $3990禾聯碩") -> $3440元大美債, $2291台企銀, $1653兆豐金, $2590合庫金, $890高雄銀, $1690彰銀, $3990禾聯碩
A6: 45566 | B6: =SUMIFS(INDIRECT("C"&$C$70&":C"), INDIRECT("B"&$C$70&":B"), ">="&$A6, INDIRECT("B"&$C$70&":B"), "<"&$A7, INDIRECT("F"&$C$70&":F"), B$2) -> 0 | C6: =SUMIFS(INDIRECT("C"&$C$70&":C"), INDIRECT("B"&$C$70&":B"), ">="&$A6, INDIRECT("B"&$C$70&":B"), "<"&$A7, INDIRECT("F"&$C$70&":F"), C$2) -> 0 | D6: =SUMIFS(INDIRECT("C"&$C$70&":C"), INDIRECT("B"&$C$70&":B"), ">="&$A6, INDIRECT("B"&$C$70&":B"), "<"&$A7, INDIRECT("F"&$C$70&":F"), D$2) -> 75500 | E6: =IFERROR(__xludf.DUMMYFUNCTION("TEXTJOIN("", "", TRUE, FILTER(INDIRECT(""U""&$C$70&"":U""), INDIRECT(""E""&$C$70&"":E"") = $B$1, INDIRECT(""B""&$C$70&"":B"") >= $A6, INDIRECT(""B""&$C$70&"":B"") <$A7))"),"") | F6: =SUMIFS(INDIRECT("C"&$C$70&":C"), INDIRECT("B"&$C$70&":B"), ">="&$A6, INDIRECT("B"&$C$70&":B"), "<"&$A7, INDIRECT("G"&$C$70&":G"), F$2) -> 6970 | G6: =SUMIFS(INDIRECT("C"&$C$70&":C"), INDIRECT("B"&$C$70&":B"), ">="&$A6, INDIRECT("B"&$C$70&":B"), "<"&$A7, INDIRECT("G"&$C$70&":G"), G$2) -> 0 | H6: =SUMIFS(INDIRECT("C"&$C$70&":C"), INDIRECT("B"&$C$70&":B"), ">="&$A6, INDIRECT("B"&$C$70&":B"), "<"&$A7, INDIRECT("G"&$C$70&":G"), H$2) -> 0 | I6: =SUMIFS(INDIRECT("C"&$C$70&":C"), INDIRECT("B"&$C$70&":B"), ">="&$A6, INDIRECT("B"&$C$70&":B"), "<"&$A7, INDIRECT("G"&$C$70&":G"), I$2) -> 0 | J6: =SUMIFS(INDIRECT("C"&$C$70&":C"), INDIRECT("B"&$C$70&":B"), ">="&$A6, INDIRECT("B"&$C$70&":B"), "<"&$A7, INDIRECT("G"&$C$70&":G"), J$2) -> 5000 | K6: =SUMIFS(INDIRECT("C"&$C$70&":C"), INDIRECT("B"&$C$70&":B"), ">="&$A6, INDIRECT("B"&$C$70&":B"), "<"&$A7, INDIRECT("G"&$C$70&":G"), K$2) -> 0 | L6: =IFERROR(__xludf.DUMMYFUNCTION("TEXTJOIN("", "", TRUE, FILTER(INDIRECT(""U""&$C$70&"":U""), INDIRECT(""E""&$C$70&"":E"") = $F$1, INDIRECT(""B""&$C$70&"":B"") >= $A6, INDIRECT(""B""&$C$70&"":B"") <$A7))"),"$5000文心1, $2290元大A級, $4190國泰美債, $490興富發") -> $5000文心1, $2290元大A級, $4190國泰美債, $490興富發
A7: 45597 | B7: =SUMIFS(INDIRECT("C"&$C$70&":C"), INDIRECT("B"&$C$70&":B"), ">="&$A7, INDIRECT("B"&$C$70&":B"), "<"&$A8, INDIRECT("F"&$C$70&":F"), B$2) -> 102900 | C7: =SUMIFS(INDIRECT("C"&$C$70&":C"), INDIRECT("B"&$C$70&":B"), ">="&$A7, INDIRECT("B"&$C$70&":B"), "<"&$A8, INDIRECT("F"&$C$70&":F"), C$2) -> 20000 | D7: =SUMIFS(INDIRECT("C"&$C$70&":C"), INDIRECT("B"&$C$70&":B"), ">="&$A7, INDIRECT("B"&$C$70&":B"), "<"&$A8, INDIRECT("F"&$C$70&":F"), D$2) -> 0 | E7: =IFERROR(__xludf.DUMMYFUNCTION("TEXTJOIN("", "", TRUE, FILTER(INDIRECT(""U""&$C$70&"":U""), INDIRECT(""E""&$C$70&"":E"") = $B$1, INDIRECT(""B""&$C$70&"":B"") >= $A7, INDIRECT(""B""&$C$70&"":B"") <$A8))"),"$20000旅遊補助") -> $20000旅遊補助 | F7: =SUMIFS(INDIRECT("C"&$C$70&":C"), INDIRECT("B"&$C$70&":B"), ">="&$A7, INDIRECT("B"&$C$70&":B"), "<"&$A8, INDIRECT("G"&$C$70&":G"), F$2) -> 4748 | G7: =SUMIFS(INDIRECT("C"&$C$70&":C"), INDIRECT("B"&$C$70&":B"), ">="&$A7, INDIRECT("B"&$C$70&":B"), "<"&$A8, INDIRECT("G"&$C$70&":G"), G$2) -> 0 | H7: =SUMIFS(INDIRECT("C"&$C$70&":C"), INDIRECT("B"&$C$70&":B"), ">="&$A7, INDIRECT("B"&$C$70&":B"), "<"&$A8, INDIRECT("G"&$C$70&":G"), H$2) -> 0 | I7: =SUMIFS(INDIRECT("C"&$C$70&":C"), INDIRECT("B"&$C$70&":B"), ">="&$A7, INDIRECT("B"&$C$70&":B"), "<"&$A8, INDIRECT("G"&$C$70&":G"), I$2) -> 0 | J7: =SUMIFS(INDIRECT("C"&$C$70&":C"), INDIRECT("B"&$C$70&":B"), ">="&$A7, INDIRECT("B"&$C$70&":B"), "<"&$A8, INDIRECT("G"&$C$70&":G"), J$2) -> 5000 | K7: =SUMIFS(INDIRECT("C"&$C$70&":C"), INDIRECT("B"&$C$70&":B"), ">="&$A7, INDIRECT("B"&$C$70&":B"), "<"&$A8, INDIRECT("G"&$C$70&":G"), K$2) -> 0 | L7: =IFERROR(__xludf.DUMMYFUNCTION("TEXTJOIN("", "", TRUE, FILTER(INDIRECT(""U""&$C$70&"":U""), INDIRECT(""E""&$C$70&"":E"") = $F$1, INDIRECT(""B""&$C$70&"":B"") >= $A7, INDIRECT(""B""&$C$70&"":B"") <$A8))"),"$5000文心1, $3953台灣中小, $795中信優息") -> $5000文心1, $3953台灣中小, $795中信優息
A8: 45627 | B8: =SUMIFS(INDIRECT("C"&$C$70&":C"), INDIRECT("B"&$C$70&":B"), ">="&$A8, INDIRECT("B"&$C$70&":B"), "<"&$A9, INDIRECT("F"&$C$70&":F"), B$2) -> 102900 | C8: =SUMIFS(INDIRECT("C"&$C$70&":C"), INDIRECT("B"&$C$70&":B"), ">="&$A8, INDIRECT("B"&$C$70&":B"), "<"&$A9, INDIRECT("F"&$C$70&":F"), C$2) -> 0 | D8: =SUMIFS(INDIRECT("C"&$C$70&":C"), INDIRECT("B"&$C$70&":B"), ">="&$A8, INDIRECT("B"&$C$70&":B"), "<"&$A9, INDIRECT("F"&$C$70&":F"), D$2) -> 0 | E8: =IFERROR(__xludf.DUMMYFUNCTION("TEXTJOIN("", "", TRUE, FILTER(INDIRECT(""U""&$C$70&"":U""), INDIRECT(""E""&$C$70&"":E"") = $B$1, INDIRECT(""B""&$C$70&"":B"") >= $A8, INDIRECT(""B""&$C$70&"":B"") <$A9))"),"") | F8: =SUMIFS(INDIRECT("C"&$C$70&":C"), INDIRECT("B"&$C$70&":B"), ">="&$A8, INDIRECT("B"&$C$70&":B"), "<"&$A9, INDIRECT("G"&$C$70&":G"), F$2) -> 7350 | G8: =SUMIFS(INDIRECT("C"&$C$70&":C"), INDIRECT("B"&$C$70&":B"), ">="&$A8, INDIRECT("B"&$C$70&":B"), "<"&$A9, INDIRECT("G"&$C$70&":G"), G$2) -> 4000 | H8: =SUMIFS(INDIRECT("C"&$C$70&":C"), INDIRECT("B"&$C$70&":B"), ">="&$A8, INDIRECT("B"&$C$70&":B"), "<"&$A9, INDIRECT("G"&$C$70&":G"), H$2) -> 0 | I8: =SUMIFS(INDIRECT("C"&$C$70&":C"), INDIRECT("B"&$C$70&":B"), ">="&$A8, INDIRECT("B"&$C$70&":B"), "<"&$A9, INDIRECT("G"&$C$70&":G"), I$2) -> 0 | J8: =SUMIFS(INDIRECT("C"&$C$70&":C"), INDIRECT("B"&$C$70&":B"), ">="&$A8, INDIRECT("B"&$C$70&":B"), "<"&$A9, INDIRECT("G"&$C$70&":G"), J$2) -> 5000 | K8: =SUMIFS(INDIRECT("C"&$C$70&":C"), INDIRECT("B"&$C$70&":B"), ">="&$A8, INDIRECT("B"&$C$70&":B"), "<"&$A9, INDIRECT("G"&$C$70&":G"), K$2) -> 0 | L8: =IFERROR(__xludf.DUMMYFUNCTION("TEXTJOIN("", "", TRUE, FILTER(INDIRECT(""U""&$C$70&"":U""), INDIRECT(""E""&$C$70&"":E"") = $F$1, INDIRECT(""B""&$C$70&"":B"") >= $A8, INDIRECT(""B""&$C$70&"":B"") <$A9))"),"$4000發票中獎, $440富邦台50, $5090美債20, $1820中信優息") -> $4000發票中獎, $440富邦台50, $5090美債20, $1820中信優息
A9: 45658 | B9: =SUMIFS(INDIRECT("C"&$C$70&":C"), INDIRECT("B"&$C$70&":B"), ">="&$A9, INDIRECT("B"&$C$70&":B"), "<"&$A10, INDIRECT("F"&$C$70&":F"), B$2) -> 102900 | C9: =SUMIFS(INDIRECT("C"&$C$70&":C"), INDIRECT("B"&$C$70&":B"), ">="&$A9, INDIRECT("B"&$C$70&":B"), "<"&$A10, INDIRECT("F"&$C$70&":F"), C$2) -> 447 | D9: =SUMIFS(INDIRECT("C"&$C$70&":C"), INDIRECT("B"&$C$70&":B"), ">="&$A9, INDIRECT("B"&$C$70&":B"), "<"&$A10, INDIRECT("F"&$C$70&":F"), D$2) -> 536987 | E9: =IFERROR(__xludf.DUMMYFUNCTION("TEXTJOIN("", "", TRUE, FILTER(INDIRECT(""U""&$C$70&"":U""), INDIRECT(""E""&$C$70&"":E"") = $B$1, INDIRECT(""B""&$C$70&"":B"") >= $A9, INDIRECT(""B""&$C$70&"":B"") <$A10))"),"$536987註1, $447調休") -> $536987註1, $447調休 | F9: =SUMIFS(INDIRECT("C"&$C$70&":C"), INDIRECT("B"&$C$70&":B"), ">="&$A9, INDIRECT("B"&$C$70&":B"), "<"&$A10, INDIRECT("G"&$C$70&":G"), F$2) -> 8710 | G9: =SUMIFS(INDIRECT("C"&$C$70&":C"), INDIRECT("B"&$C$70&":B"), ">="&$A9, INDIRECT("B"&$C$70&":B"), "<"&$A10, INDIRECT("G"&$C$70&":G"), G$2) -> 3659 | H9: =SUMIFS(INDIRECT("C"&$C$70&":C"), INDIRECT("B"&$C$70&":B"), ">="&$A9, INDIRECT("B"&$C$70&":B"), "<"&$A10, INDIRECT("G"&$C$70&":G"), H$2) -> 0 | I9: =SUMIFS(INDIRECT("C"&$C$70&":C"), INDIRECT("B"&$C$70&":B"), ">="&$A9, INDIRECT("B"&$C$70&":B"), "<"&$A10, INDIRECT("G"&$C$70&":G"), I$2) -> 0 | J9: =SUMIFS(INDIRECT("C"&$C$70&":C"), INDIRECT("B"&$C$70&":B"), ">="&$A9, INDIRECT("B"&$C$70&":B"), "<"&$A10, INDIRECT("G"&$C$70&":G"), J$2) -> 5000 | K9: =SUMIFS(INDIRECT("C"&$C$70&":C"), INDIRECT("B"&$C$70&":B"), ">="&$A9, INDIRECT("B"&$C$70&":B"), "<"&$A10, INDIRECT("G"&$C$70&":G"), K$2) -> 0 | L9: =IFERROR(__xludf.DUMMYFUNCTION("TEXTJOIN("", "", TRUE, FILTER(INDIRECT(""U""&$C$70&"":U""), INDIRECT(""E""&$C$70&"":E"") = $F$1, INDIRECT(""B""&$C$70&"":B"") >= $A9, INDIRECT(""B""&$C$70&"":B"") <$A10))"),"$3659紅包自己抽寶, $6890元大A級, $1820中信優息") -> $3659紅包自己抽寶, $6890元大A級, $1820中信優息
A10: 45689 | B10: =SUMIFS(INDIRECT("C"&$C$70&":C"), INDIRECT("B"&$C$70&":B"), ">="&$A10, INDIRECT("B"&$C$70&":B"), "<"&$A11, INDIRECT("F"&$C$70&":F"), B$2) -> 101185 | C10: =SUMIFS(INDIRECT("C"&$C$70&":C"), INDIRECT("B"&$C$70&":B"), ">="&$A10, INDIRECT("B"&$C$70&":B"), "<"&$A11, INDIRECT("F"&$C$70&":F"), C$2) -> 0 | D10: =SUMIFS(INDIRECT("C"&$C$70&":C"), INDIRECT("B"&$C$70&":B"), ">="&$A10, INDIRECT("B"&$C$70&":B"), "<"&$A11, INDIRECT("F"&$C$70&":F"), D$2) -> 0 | E10: =IFERROR(__xludf.DUMMYFUNCTION("TEXTJOIN("", "", TRUE, FILTER(INDIRECT(""U""&$C$70&"":U""), INDIRECT(""E""&$C$70&"":E"") = $B$1, INDIRECT(""B""&$C$70&"":B"") >= $A10, INDIRECT(""B""&$C$70&"":B"") <$A11))"),"$101185含請假扣款") -> $101185含請假扣款 | F10: =SUMIFS(INDIRECT("C"&$C$70&":C"), INDIRECT("B"&$C$70&":B"), ">="&$A10, INDIRECT("B"&$C$70&":B"), "<"&$A11, INDIRECT("G"&$C$70&":G"), F$2) -> 1680 | G10: =SUMIFS(INDIRECT("C"&$C$70&":C"), INDIRECT("B"&$C$70&":B"), ">="&$A10, INDIRECT("B"&$C$70&":B"), "<"&$A11, INDIRECT("G"&$C$70&":G"), G$2) -> 0 | H10: =SUMIFS(INDIRECT("C"&$C$70&":C"), INDIRECT("B"&$C$70&":B"), ">="&$A10, INDIRECT("B"&$C$70&":B"), "<"&$A11, INDIRECT("G"&$C$70&":G"), H$2) -> 0 | I10: =SUMIFS(INDIRECT("C"&$C$70&":C"), INDIRECT("B"&$C$70&":B"), ">="&$A10, INDIRECT("B"&$C$70&":B"), "<"&$A11, INDIRECT("G"&$C$70&":G"), I$2) -> 0 | J10: =SUMIFS(INDIRECT("C"&$C$70&":C"), INDIRECT("B"&$C$70&":B"), ">="&$A10, INDIRECT("B"&$C$70&":B"), "<"&$A11, INDIRECT("G"&$C$70&":G"), J$2) -> 5000 | K10: =SUMIFS(INDIRECT("C"&$C$70&":C"), INDIRECT("B"&$C$70&":B"), ">="&$A10, INDIRECT("B"&$C$70&":B"), "<"&$A11, INDIRECT("G"&$C$70&":G"), K$2) -> 500 | L10: =IFERROR(__xludf.DUMMYFUNCTION("TEXTJOIN("", "", TRUE, FILTER(INDIRECT(""U""&$C$70&"":U""), INDIRECT(""E""&$C$70&"":E"") = $F$1, INDIRECT(""B""&$C$70&"":B"") >= $A10, INDIRECT(""B""&$C$70&"":B"") <$A11))"),"$500除濕機退稅, $1680中信優息") -> $500除濕機退稅, $1680中信優息
A11: 45717 | B11: =SUMIFS(INDIRECT("C"&$C$70&":C"), INDIRECT("B"&$C$70&":B"), ">="&$A11, INDIRECT("B"&$C$70&":B"), "<"&$A12, INDIRECT("F"&$C$70&":F"), B$2) -> 101078 | C11: =SUMIFS(INDIRECT("C"&$C$70&":C"), INDIRECT("B"&$C$70&":B"), ">="&$A11, INDIRECT("B"&$C$70&":B"), "<"&$A12, INDIRECT("F"&$C$70&":F"), C$2) -> 7563 | D11: =SUMIFS(INDIRECT("C"&$C$70&":C"), INDIRECT("B"&$C$70&":B"), ">="&$A11, INDIRECT("B"&$C$70&":B"), "<"&$A12, INDIRECT("F"&$C$70&":F"), D$2) -> 0 | E11: =IFERROR(__xludf.DUMMYFUNCTION("TEXTJOIN("", "", TRUE, FILTER(INDIRECT(""U""&$C$70&"":U""), INDIRECT(""E""&$C$70&"":E"") = $B$1, INDIRECT(""B""&$C$70&"":B"") >= $A11, INDIRECT(""B""&$C$70&"":B"") <$A12))"),"$101078 $1822請假扣款, $7443加班, $120加班誤餐費") -> $101078 $1822請假扣款, $7443加班, $120加班誤餐費 | F11: =SUMIFS(INDIRECT("C"&$C$70&":C"), INDIRECT("B"&$C$70&":B"), ">="&$A11, INDIRECT("B"&$C$70&":B"), "<"&$A12, INDIRECT("G"&$C$70&":G"), F$2) -> 6930 | G11: =SUMIFS(INDIRECT("C"&$C$70&":C"), INDIRECT("B"&$C$70&":B"), ">="&$A11, INDIRECT("B"&$C$70&":B"), "<"&$A12, INDIRECT("G"&$C$70&":G"), G$2) -> 0 | H11: =SUMIFS(INDIRECT("C"&$C$70&":C"), INDIRECT("B"&$C$70&":B"), ">="&$A11, INDIRECT("B"&$C$70&":B"), "<"&$A12, INDIRECT("G"&$C$70&":G"), H$2) -> 0 | I11: =SUMIFS(INDIRECT("C"&$C$70&":C"), INDIRECT("B"&$C$70&":B"), ">="&$A11, INDIRECT("B"&$C$70&":B"), "<"&$A12, INDIRECT("G"&$C$70&":G"), I$2) -> 0 | J11: =SUMIFS(INDIRECT("C"&$C$70&":C"), INDIRECT("B"&$C$70&":B"), ">="&$A11, INDIRECT("B"&$C$70&":B"), "<"&$A12, INDIRECT("G"&$C$70&":G"), J$2) -> 5000 | K11: =SUMIFS(INDIRECT("C"&$C$70&":C"), INDIRECT("B"&$C$70&":B"), ">="&$A11, INDIRECT("B"&$C$70&":B"), "<"&$A12, INDIRECT("G"&$C$70&":G"), K$2) -> 0 | L11: =IFERROR(__xludf.DUMMYFUNCTION("TEXTJOIN("", "", TRUE, FILTER(INDIRECT(""U""&$C$70&"":U""), INDIRECT(""E""&$C$70&"":E"") = $F$1, INDIRECT(""B""&$C$70&"":B"") >= $A11, INDIRECT(""B""&$C$70&"":B"") <$A12))"),"$2430中信優息, $4500元大美債") -> $2430中信優息, $4500元大美債
A12: 45748 | B12: =SUMIFS(INDIRECT("C"&$C$70&":C"), INDIRECT("B"&$C$70&":B"), ">="&$A12, INDIRECT("B"&$C$70&":B"), "<"&$A13, INDIRECT("F"&$C$70&":F"), B$2) -> 102364 | C12: =SUMIFS(INDIRECT("C"&$C$70&":C"), INDIRECT("B"&$C$70&":B"), ">="&$A12, INDIRECT("B"&$C$70&":B"), "<"&$A13, INDIRECT("F"&$C$70&":F"), C$2) -> 1000 | D12: =SUMIFS(INDIRECT("C"&$C$70&":C"), INDIRECT("B"&$C$70&":B"), ">="&$A12, INDIRECT("B"&$C$70&":B"), "<"&$A13, INDIRECT("F"&$C$70&":F"), D$2) -> 75500 | E12: =IFERROR(__xludf.DUMMYFUNCTION("TEXTJOIN("", "", TRUE, FILTER(INDIRECT(""U""&$C$70&"":U""), INDIRECT(""E""&$C$70&"":E"") = $B$1, INDIRECT(""B""&$C$70&"":B"") >= $A12, INDIRECT(""B""&$C$70&"":B"") <$A13))"),"$102364 $536請假扣款, $1000勞動節, $75500績效") -> $102364 $536請假扣款, $1000勞動節, $75500績效 | F12: =SUMIFS(INDIRECT("C"&$C$70&":C"), INDIRECT("B"&$C$70&":B"), ">="&$A12, INDIRECT("B"&$C$70&":B"), "<"&$A13, INDIRECT("G"&$C$70&":G"), F$2) -> 9782 | G12: =SUMIFS(INDIRECT("C"&$C$70&":C"), INDIRECT("B"&$C$70&":B"), ">="&$A12, INDIRECT("B"&$C$70&":B"), "<"&$A13, INDIRECT("G"&$C$70&":G"), G$2) -> 0 | H12: =SUMIFS(INDIRECT("C"&$C$70&":C"), INDIRECT("B"&$C$70&":B"), ">="&$A12, INDIRECT("B"&$C$70&":B"), "<"&$A13, INDIRECT("G"&$C$70&":G"), H$2) -> 0 | I12: =SUMIFS(INDIRECT("C"&$C$70&":C"), INDIRECT("B"&$C$70&":B"), ">="&$A12, INDIRECT("B"&$C$70&":B"), "<"&$A13, INDIRECT("G"&$C$70&":G"), I$2) -> 0 | J12: =SUMIFS(INDIRECT("C"&$C$70&":C"), INDIRECT("B"&$C$70&":B"), ">="&$A12, INDIRECT("B"&$C$70&":B"), "<"&$A13, INDIRECT("G"&$C$70&":G"), J$2) -> 6000 | K12: =SUMIFS(INDIRECT("C"&$C$70&":C"), INDIRECT("B"&$C$70&":B"), ">="&$A12, INDIRECT("B"&$C$70&":B"), "<"&$A13, INDIRECT("G"&$C$70&":G"), K$2) -> 0 | L12: =IFERROR(__xludf.DUMMYFUNCTION("TEXTJOIN("", "", TRUE, FILTER(INDIRECT(""U""&$C$70&"":U""), INDIRECT(""E""&$C$70&"":E"") = $F$1, INDIRECT(""B""&$C$70&"":B"") >= $A12, INDIRECT(""B""&$C$70&"":B"") <$A13))"),"$2592中信優息, $7190元大A級") -> $2592中信優息, $7190元大A級
A13: 45778 | B13: =SUMIFS(INDIRECT("C"&$C$70&":C"), INDIRECT("B"&$C$70&":B"), ">="&$A13, INDIRECT("B"&$C$70&":B"), "<"&$A14, INDIRECT("F"&$C$70&":F"), B$2) -> 100649 | C13: =SUMIFS(INDIRECT("C"&$C$70&":C"), INDIRECT("B"&$C$70&":B"), ">="&$A13, INDIRECT("B"&$C$70&":B"), "<"&$A14, INDIRECT("F"&$C$70&":F"), C$2) -> 1000 | D13: =SUMIFS(INDIRECT("C"&$C$70&":C"), INDIRECT("B"&$C$70&":B"), ">="&$A13, INDIRECT("B"&$C$70&":B"), "<"&$A14, INDIRECT("F"&$C$70&":F"), D$2) -> 0 | E13: =IFERROR(__xludf.DUMMYFUNCTION("TEXTJOIN("", "", TRUE, FILTER(INDIRECT(""U""&$C$70&"":U""), INDIRECT(""E""&$C$70&"":E"") = $B$1, INDIRECT(""B""&$C$70&"":B"") >= $A13, INDIRECT(""B""&$C$70&"":B"") <$A14))"),"$100649 $2251請假扣款, $1000端午節") -> $100649 $2251請假扣款, $1000端午節 | F13: =SUMIFS(INDIRECT("C"&$C$70&":C"), INDIRECT("B"&$C$70&":B"), ">="&$A13, INDIRECT("B"&$C$70&":B"), "<"&$A14, INDIRECT("G"&$C$70&":G"), F$2) -> 2874 | G13: =SUMIFS(INDIRECT("C"&$C$70&":C"), INDIRECT("B"&$C$70&":B"), ">="&$A13, INDIRECT("B"&$C$70&":B"), "<"&$A14, INDIRECT("G"&$C$70&":G"), G$2) -> 0 | H13: =SUMIFS(INDIRECT("C"&$C$70&":C"), INDIRECT("B"&$C$70&":B"), ">="&$A13, INDIRECT("B"&$C$70&":B"), "<"&$A14, INDIRECT("G"&$C$70&":G"), H$2) -> 0 | I13: =SUMIFS(INDIRECT("C"&$C$70&":C"), INDIRECT("B"&$C$70&":B"), ">="&$A13, INDIRECT("B"&$C$70&":B"), "<"&$A14, INDIRECT("G"&$C$70&":G"), I$2) -> 0 | J13: =SUMIFS(INDIRECT("C"&$C$70&":C"), INDIRECT("B"&$C$70&":B"), ">="&$A13, INDIRECT("B"&$C$70&":B"), "<"&$A14, INDIRECT("G"&$C$70&":G"), J$2) -> 6000 | K13: =SUMIFS(INDIRECT("C"&$C$70&":C"), INDIRECT("B"&$C$70&":B"), ">="&$A13, INDIRECT("B"&$C$70&":B"), "<"&$A14, INDIRECT("G"&$C$70&":G"), K$2) -> 0 | L13: =IFERROR(__xludf.DUMMYFUNCTION("TEXTJOIN("", "", TRUE, FILTER(INDIRECT(""U""&$C$70&"":U""), INDIRECT(""E""&$C$70&"":E"") = $F$1, INDIRECT(""B""&$C$70&"":B"") >= $A13, INDIRECT(""B""&$C$70&"":B"") <$A14))"),"$282台灣中小, $2592中信優息") -> $282台灣中小, $2592中信優息
A14: 45809 | B14: =SUMIFS(INDIRECT("C"&$C$70&":C"), INDIRECT("B"&$C$70&":B"), ">="&$A14, INDIRECT("B"&$C$70&":B"), "<"&$A15, INDIRECT("F"&$C$70&":F"), B$2) -> 107300 | C14: =SUMIFS(INDIRECT("C"&$C$70&":C"), INDIRECT("B"&$C$70&":B"), ">="&$A14, INDIRECT("B"&$C$70&":B"), "<"&$A15, INDIRECT("F"&$C$70&":F"), C$2) -> 0 | D14: =SUMIFS(INDIRECT("C"&$C$70&":C"), INDIRECT("B"&$C$70&":B"), ">="&$A14, INDIRECT("B"&$C$70&":B"), "<"&$A15, INDIRECT("F"&$C$70&":F"), D$2) -> 0 | E14: =IFERROR(__xludf.DUMMYFUNCTION("TEXTJOIN("", "", TRUE, FILTER(INDIRECT(""U""&$C$70&"":U""), INDIRECT(""E""&$C$70&"":E"") = $B$1, INDIRECT(""B""&$C$70&"":B"") >= $A14, INDIRECT(""B""&$C$70&"":B"") <$A15))"),"") | F14: =SUMIFS(INDIRECT("C"&$C$70&":C"), INDIRECT("B"&$C$70&":B"), ">="&$A14, INDIRECT("B"&$C$70&":B"), "<"&$A15, INDIRECT("G"&$C$70&":G"), F$2) -> 7856 | G14: =SUMIFS(INDIRECT("C"&$C$70&":C"), INDIRECT("B"&$C$70&":B"), ">="&$A14, INDIRECT("B"&$C$70&":B"), "<"&$A15, INDIRECT("G"&$C$70&":G"), G$2) -> 0 | H14: =SUMIFS(INDIRECT("C"&$C$70&":C"), INDIRECT("B"&$C$70&":B"), ">="&$A14, INDIRECT("B"&$C$70&":B"), "<"&$A15, INDIRECT("G"&$C$70&":G"), H$2) -> 0 | I14: =SUMIFS(INDIRECT("C"&$C$70&":C"), INDIRECT("B"&$C$70&":B"), ">="&$A14, INDIRECT("B"&$C$70&":B"), "<"&$A15, INDIRECT("G"&$C$70&":G"), I$2) -> 0 | J14: =SUMIFS(INDIRECT("C"&$C$70&":C"), INDIRECT("B"&$C$70&":B"), ">="&$A14, INDIRECT("B"&$C$70&":B"), "<"&$A15, INDIRECT("G"&$C$70&":G"), J$2) -> 6000 | K14: =SUMIFS(INDIRECT("C"&$C$70&":C"), INDIRECT("B"&$C$70&":B"), ">="&$A14, INDIRECT("B"&$C$70&":B"), "<"&$A15, INDIRECT("G"&$C$70&":G"), K$2) -> 0 | L14: =IFERROR(__xludf.DUMMYFUNCTION("TEXTJOIN("", "", TRUE, FILTER(INDIRECT(""U""&$C$70&"":U""), INDIRECT(""E""&$C$70&"":E"") = $F$1, INDIRECT(""B""&$C$70&"":B"") >= $A14, INDIRECT(""B""&$C$70&"":B"") <$A15))"),"$2736中信優息, $5120元大美債") -> $2736中信優息, $5120元大美債
A15: 45839 | B15: =SUMIFS(INDIRECT("C"&$C$70&":C"), INDIRECT("B"&$C$70&":B"), ">="&$A15, INDIRECT("B"&$C$70&":B"), "<"&$A16, INDIRECT("F"&$C$70&":F"), B$2) -> 107300 | C15: =SUMIFS(INDIRECT("C"&$C$70&":C"), INDIRECT("B"&$C$70&":B"), ">="&$A15, INDIRECT("B"&$C$70&":B"), "<"&$A16, INDIRECT("F"&$C$70&":F"), C$2) -> 0 | D15: =SUMIFS(INDIRECT("C"&$C$70&":C"), INDIRECT("B"&$C$70&":B"), ">="&$A15, INDIRECT("B"&$C$70&":B"), "<"&$A16, INDIRECT("F"&$C$70&":F"), D$2) -> 101000 | E15: =IFERROR(__xludf.DUMMYFUNCTION("TEXTJOIN("", "", TRUE, FILTER(INDIRECT(""U""&$C$70&"":U""), INDIRECT(""E""&$C$70&"":E"") = $B$1, INDIRECT(""B""&$C$70&"":B"") >= $A15, INDIRECT(""B""&$C$70&"":B"") <$A16))"),"") | F15: =SUMIFS(INDIRECT("C"&$C$70&":C"), INDIRECT("B"&$C$70&":B"), ">="&$A15, INDIRECT("B"&$C$70&":B"), "<"&$A16, INDIRECT("G"&$C$70&":G"), F$2) -> 21532 | G15: =SUMIFS(INDIRECT("C"&$C$70&":C"), INDIRECT("B"&$C$70&":B"), ">="&$A15, INDIRECT("B"&$C$70&":B"), "<"&$A16, INDIRECT("G"&$C$70&":G"), G$2) -> 0 | H15: =SUMIFS(INDIRECT("C"&$C$70&":C"), INDIRECT("B"&$C$70&":B"), ">="&$A15, INDIRECT("B"&$C$70&":B"), "<"&$A16, INDIRECT("G"&$C$70&":G"), H$2) -> 0 | I15: =SUMIFS(INDIRECT("C"&$C$70&":C"), INDIRECT("B"&$C$70&":B"), ">="&$A15, INDIRECT("B"&$C$70&":B"), "<"&$A16, INDIRECT("G"&$C$70&":G"), I$2) -> 0 | J15: =SUMIFS(INDIRECT("C"&$C$70&":C"), INDIRECT("B"&$C$70&":B"), ">="&$A15, INDIRECT("B"&$C$70&":B"), "<"&$A16, INDIRECT("G"&$C$70&":G"), J$2) -> 6000 | K15: =SUMIFS(INDIRECT("C"&$C$70&":C"), INDIRECT("B"&$C$70&":B"), ">="&$A15, INDIRECT("B"&$C$70&":B"), "<"&$A16, INDIRECT("G"&$C$70&":G"), K$2) -> 0 | L15: =IFERROR(__xludf.DUMMYFUNCTION("TEXTJOIN("", "", TRUE, FILTER(INDIRECT(""U""&$C$70&"":U""), INDIRECT(""E""&$C$70&"":E"") = $F$1, INDIRECT(""B""&$C$70&"":B"") >= $A15, INDIRECT(""B""&$C$70&"":B"") <$A16))"),"$6960元大A級, $2622中信優息, $3790中再保, $1540元大金, $4040遠百, $890正隆, $1690凱基金") -> $6960元大A級, $2622中信優息, $3790中再保, $1540元大金, $4040遠百, $890正隆, $1690凱基金
A16: 45870 | B16: =SUMIFS(INDIRECT("C"&$C$70&":C"), INDIRECT("B"&$C$70&":B"), ">="&$A16, INDIRECT("B"&$C$70&":B"), "<"&$A17, INDIRECT("F"&$C$70&":F"), B$2) -> 106741 | C16: =SUMIFS(INDIRECT("C"&$C$70&":C"), INDIRECT("B"&$C$70&":B"), ">="&$A16, INDIRECT("B"&$C$70&":B"), "<"&$A17, INDIRECT("F"&$C$70&":F"), C$2) -> 28459 | D16: =SUMIFS(INDIRECT("C"&$C$70&":C"), INDIRECT("B"&$C$70&":B"), ">="&$A16, INDIRECT("B"&$C$70&":B"), "<"&$A17, INDIRECT("F"&$C$70&":F"), D$2) -> 0 | E16: =IFERROR(__xludf.DUMMYFUNCTION("TEXTJOIN("", "", TRUE, FILTER(INDIRECT(""U""&$C$70&"":U""), INDIRECT(""E""&$C$70&"":E"") = $B$1, INDIRECT(""B""&$C$70&"":B"") >= $A16, INDIRECT(""B""&$C$70&"":B"") <$A17))"),"$106741 559病假, $2459特休, $5000體檢費, $1000生日禮金, $20000旅遊補助") -> $106741 559病假, $2459特休, $5000體檢費, $1000生日禮金, $20000旅遊補助 | F16: =SUMIFS(INDIRECT("C"&$C$70&":C"), INDIRECT("B"&$C$70&":B"), ">="&$A16, INDIRECT("B"&$C$70&":B"), "<"&$A17, INDIRECT("G"&$C$70&":G"), F$2) -> 17441 | G16: =SUMIFS(INDIRECT("C"&$C$70&":C"), INDIRECT("B"&$C$70&":B"), ">="&$A16, INDIRECT("B"&$C$70&":B"), "<"&$A17, INDIRECT("G"&$C$70&":G"), G$2) -> 0 | H16: =SUMIFS(INDIRECT("C"&$C$70&":C"), INDIRECT("B"&$C$70&":B"), ">="&$A16, INDIRECT("B"&$C$70&":B"), "<"&$A17, INDIRECT("G"&$C$70&":G"), H$2) -> 0 | I16: =SUMIFS(INDIRECT("C"&$C$70&":C"), INDIRECT("B"&$C$70&":B"), ">="&$A16, INDIRECT("B"&$C$70&":B"), "<"&$A17, INDIRECT("G"&$C$70&":G"), I$2) -> 0 | J16: =SUMIFS(INDIRECT("C"&$C$70&":C"), INDIRECT("B"&$C$70&":B"), ">="&$A16, INDIRECT("B"&$C$70&":B"), "<"&$A17, INDIRECT("G"&$C$70&":G"), J$2) -> 6000 | K16: =SUMIFS(INDIRECT("C"&$C$70&":C"), INDIRECT("B"&$C$70&":B"), ">="&$A16, INDIRECT("B"&$C$70&":B"), "<"&$A17, INDIRECT("G"&$C$70&":G"), K$2) -> 0 | L16: =IFERROR(__xludf.DUMMYFUNCTION("TEXTJOIN("", "", TRUE, FILTER(INDIRECT(""U""&$C$70&"":U""), INDIRECT(""E""&$C$70&"":E"") = $F$1, INDIRECT(""B""&$C$70&"":B"") >= $A16, INDIRECT(""B""&$C$70&"":B"") <$A17))"),"$1674玉山金, $2508中信優息, $890山隆, $2290中信金, $8990海悅, $1089聯邦銀") -> $1674玉山金, $2508中信優息, $890山隆, $2290中信金, $8990海悅, $1089聯邦銀
A17: 45901 | B17: =SUMIFS(INDIRECT("C"&$C$70&":C"), INDIRECT("B"&$C$70&":B"), ">="&$A17, INDIRECT("B"&$C$70&":B"), "<"&$A18, INDIRECT("F"&$C$70&":F"), B$2) -> 107076 | C17: =SUMIFS(INDIRECT("C"&$C$70&":C"), INDIRECT("B"&$C$70&":B"), ">="&$A17, INDIRECT("B"&$C$70&":B"), "<"&$A18, INDIRECT("F"&$C$70&":F"), C$2) -> 0 | D17: =SUMIFS(INDIRECT("C"&$C$70&":C"), INDIRECT("B"&$C$70&":B"), ">="&$A17, INDIRECT("B"&$C$70&":B"), "<"&$A18, INDIRECT("F"&$C$70&":F"), D$2) -> 0 | E17: =IFERROR(__xludf.DUMMYFUNCTION("TEXTJOIN("", "", TRUE, FILTER(INDIRECT(""U""&$C$70&"":U""), INDIRECT(""E""&$C$70&"":E"") = $B$1, INDIRECT(""B""&$C$70&"":B"") >= $A17, INDIRECT(""B""&$C$70&"":B"") <$A18))"),"$107076 $224病假") -> $107076 $224病假 | F17: =SUMIFS(INDIRECT("C"&$C$70&":C"), INDIRECT("B"&$C$70&":B"), ">="&$A17, INDIRECT("B"&$C$70&":B"), "<"&$A18, INDIRECT("G"&$C$70&":G"), F$2) -> 20460 | G17: =SUMIFS(INDIRECT("C"&$C$70&":C"), INDIRECT("B"&$C$70&":B"), ">="&$A17, INDIRECT("B"&$C$70&":B"), "<"&$A18, INDIRECT("G"&$C$70&":G"), G$2) -> 0 | H17: =SUMIFS(INDIRECT("C"&$C$70&":C"), INDIRECT("B"&$C$70&":B"), ">="&$A17, INDIRECT("B"&$C$70&":B"), "<"&$A18, INDIRECT("G"&$C$70&":G"), H$2) -> 0 | I17: =SUMIFS(INDIRECT("C"&$C$70&":C"), INDIRECT("B"&$C$70&":B"), ">="&$A17, INDIRECT("B"&$C$70&":B"), "<"&$A18, INDIRECT("G"&$C$70&":G"), I$2) -> 0 | J17: =SUMIFS(INDIRECT("C"&$C$70&":C"), INDIRECT("B"&$C$70&":B"), ">="&$A17, INDIRECT("B"&$C$70&":B"), "<"&$A18, INDIRECT("G"&$C$70&":G"), J$2) -> 6000 | K17: =SUMIFS(INDIRECT("C"&$C$70&":C"), INDIRECT("B"&$C$70&":B"), ">="&$A17, INDIRECT("B"&$C$70&":B"), "<"&$A18, INDIRECT("G"&$C$70&":G"), K$2) -> 0 | L17: =IFERROR(__xludf.DUMMYFUNCTION("TEXTJOIN("", "", TRUE, FILTER(INDIRECT(""U""&$C$70&"":U""), INDIRECT(""E""&$C$70&"":E"") = $F$1, INDIRECT(""B""&$C$70&"":B"") >= $A17, INDIRECT(""B""&$C$70&"":B"") <$A18))"),"$990彰銀, $4470美債20年, $1590兆豐金, $3590台新新光, $2160中信優息, $770台中銀, $900永豐金, $5990遠東銀") -> $990彰銀, $4470美債20年, $1590兆豐金, $3590台新新光, $2160中信優息, $770台中銀, $900永豐金, $5990遠東銀
A18: 45931 | B18: =SUMIFS(INDIRECT("C"&$C$70&":C"), INDIRECT("B"&$C$70&":B"), ">="&$A18, INDIRECT("B"&$C$70&":B"), "<"&$A19, INDIRECT("F"&$C$70&":F"), B$2) -> 105065 | C18: =SUMIFS(INDIRECT("C"&$C$70&":C"), INDIRECT("B"&$C$70&":B"), ">="&$A18, INDIRECT("B"&$C$70&":B"), "<"&$A19, INDIRECT("F"&$C$70&":F"), C$2) -> 1000 | D18: =SUMIFS(INDIRECT("C"&$C$70&":C"), INDIRECT("B"&$C$70&":B"), ">="&$A18, INDIRECT("B"&$C$70&":B"), "<"&$A19, INDIRECT("F"&$C$70&":F"), D$2) -> 76000 | E18: =IFERROR(__xludf.DUMMYFUNCTION("TEXTJOIN("", "", TRUE, FILTER(INDIRECT(""U""&$C$70&"":U""), INDIRECT(""E""&$C$70&"":E"") = $B$1, INDIRECT(""B""&$C$70&"":B"") >= $A18, INDIRECT(""B""&$C$70&"":B"") <$A19))"),"$105065 $2235病假, $1000中秋節, $76000績效") -> $105065 $2235病假, $1000中秋節, $76000績效 | F18: =SUMIFS(INDIRECT("C"&$C$70&":C"), INDIRECT("B"&$C$70&":B"), ">="&$A18, INDIRECT("B"&$C$70&":B"), "<"&$A19, INDIRECT("G"&$C$70&":G"), F$2) -> 11670 | G18: =SUMIFS(INDIRECT("C"&$C$70&":C"), INDIRECT("B"&$C$70&":B"), ">="&$A18, INDIRECT("B"&$C$70&":B"), "<"&$A19, INDIRECT("G"&$C$70&":G"), G$2) -> 0 | H18: =SUMIFS(INDIRECT("C"&$C$70&":C"), INDIRECT("B"&$C$70&":B"), ">="&$A18, INDIRECT("B"&$C$70&":B"), "<"&$A19, INDIRECT("G"&$C$70&":G"), H$2) -> 0 | I18: =SUMIFS(INDIRECT("C"&$C$70&":C"), INDIRECT("B"&$C$70&":B"), ">="&$A18, INDIRECT("B"&$C$70&":B"), "<"&$A19, INDIRECT("G"&$C$70&":G"), I$2) -> 0 | J18: =SUMIFS(INDIRECT("C"&$C$70&":C"), INDIRECT("B"&$C$70&":B"), ">="&$A18, INDIRECT("B"&$C$70&":B"), "<"&$A19, INDIRECT("G"&$C$70&":G"), J$2) -> 6000 | K18: =SUMIFS(INDIRECT("C"&$C$70&":C"), INDIRECT("B"&$C$70&":B"), ">="&$A18, INDIRECT("B"&$C$70&":B"), "<"&$A19, INDIRECT("G"&$C$70&":G"), K$2) -> 0 | L18: =IFERROR(__xludf.DUMMYFUNCTION("TEXTJOIN("", "", TRUE, FILTER(INDIRECT(""U""&$C$70&"":U""), INDIRECT(""E""&$C$70&"":E"") = $F$1, INDIRECT(""B""&$C$70&"":B"") >= $A18, INDIRECT(""B""&$C$70&"":B"") <$A19))"),"$6960元大A級, $2520中信優息, $2190興富發") -> $6960元大A級, $2520中信優息, $2190興富發
A19: 45962 | B19: =SUMIFS(INDIRECT("C"&$C$70&":C"), INDIRECT("B"&$C$70&":B"), ">="&$A19, INDIRECT("B"&$C$70&":B"), "<"&$A20, INDIRECT("F"&$C$70&":F"), B$2) -> 107300 | C19: =SUMIFS(INDIRECT("C"&$C$70&":C"), INDIRECT("B"&$C$70&":B"), ">="&$A19, INDIRECT("B"&$C$70&":B"), "<"&$A20, INDIRECT("F"&$C$70&":F"), C$2) -> 0 | D19: =SUMIFS(INDIRECT("C"&$C$70&":C"), INDIRECT("B"&$C$70&":B"), ">="&$A19, INDIRECT("B"&$C$70&":B"), "<"&$A20, INDIRECT("F"&$C$70&":F"), D$2) -> 0 | E19: =IFERROR(__xludf.DUMMYFUNCTION("TEXTJOIN("", "", TRUE, FILTER(INDIRECT(""U""&$C$70&"":U""), INDIRECT(""E""&$C$70&"":E"") = $B$1, INDIRECT(""B""&$C$70&"":B"") >= $A19, INDIRECT(""B""&$C$70&"":B"") <$A20))"),"") | F19: =SUMIFS(INDIRECT("C"&$C$70&":C"), INDIRECT("B"&$C$70&":B"), ">="&$A19, INDIRECT("B"&$C$70&":B"), "<"&$A20, INDIRECT("G"&$C$70&":G"), F$2) -> 2520 | G19: =SUMIFS(INDIRECT("C"&$C$70&":C"), INDIRECT("B"&$C$70&":B"), ">="&$A19, INDIRECT("B"&$C$70&":B"), "<"&$A20, INDIRECT("G"&$C$70&":G"), G$2) -> 0 | H19: =SUMIFS(INDIRECT("C"&$C$70&":C"), INDIRECT("B"&$C$70&":B"), ">="&$A19, INDIRECT("B"&$C$70&":B"), "<"&$A20, INDIRECT("G"&$C$70&":G"), H$2) -> 0 | I19: =SUMIFS(INDIRECT("C"&$C$70&":C"), INDIRECT("B"&$C$70&":B"), ">="&$A19, INDIRECT("B"&$C$70&":B"), "<"&$A20, INDIRECT("G"&$C$70&":G"), I$2) -> 0 | J19: =SUMIFS(INDIRECT("C"&$C$70&":C"), INDIRECT("B"&$C$70&":B"), ">="&$A19, INDIRECT("B"&$C$70&":B"), "<"&$A20, INDIRECT("G"&$C$70&":G"), J$2) -> 6000 | K19: =SUMIFS(INDIRECT("C"&$C$70&":C"), INDIRECT("B"&$C$70&":B"), ">="&$A19, INDIRECT("B"&$C$70&":B"), "<"&$A20, INDIRECT("G"&$C$70&":G"), K$2) -> 0 | L19: =IFERROR(__xludf.DUMMYFUNCTION("TEXTJOIN("", "", TRUE, FILTER(INDIRECT(""U""&$C$70&"":U""), INDIRECT(""E""&$C$70&"":E"") = $F$1, INDIRECT(""B""&$C$70&"":B"") >= $A19, INDIRECT(""B""&$C$70&"":B"") <$A20))"),"$2520中信優息") -> $2520中信優息
A20: 45992 | B20: =SUMIFS(INDIRECT("C"&$C$70&":C"), INDIRECT("B"&$C$70&":B"), ">="&$A20, INDIRECT("B"&$C$70&":B"), "<"&$A21, INDIRECT("F"&$C$70&":F"), B$2) -> 107300 | C20: =SUMIFS(INDIRECT("C"&$C$70&":C"), INDIRECT("B"&$C$70&":B"), ">="&$A20, INDIRECT("B"&$C$70&":B"), "<"&$A21, INDIRECT("F"&$C$70&":F"), C$2) -> 25000 | D20: =SUMIFS(INDIRECT("C"&$C$70&":C"), INDIRECT("B"&$C$70&":B"), ">="&$A20, INDIRECT("B"&$C$70&":B"), "<"&$A21, INDIRECT("F"&$C$70&":F"), D$2) -> 0 | E20: =IFERROR(__xludf.DUMMYFUNCTION("TEXTJOIN("", "", TRUE, FILTER(INDIRECT(""U""&$C$70&"":U""), INDIRECT(""E""&$C$70&"":E"") = $B$1, INDIRECT(""B""&$C$70&"":B"") >= $A20, INDIRECT(""B""&$C$70&"":B"") <$A21))"),"$25000家庭日") -> $25000家庭日 | F20: =SUMIFS(INDIRECT("C"&$C$70&":C"), INDIRECT("B"&$C$70&":B"), ">="&$A20, INDIRECT("B"&$C$70&":B"), "<"&$A21, INDIRECT("G"&$C$70&":G"), F$2) -> 6990 | G20: =SUMIFS(INDIRECT("C"&$C$70&":C"), INDIRECT("B"&$C$70&":B"), ">="&$A20, INDIRECT("B"&$C$70&":B"), "<"&$A21, INDIRECT("G"&$C$70&":G"), G$2) -> 0 | H20: =SUMIFS(INDIRECT("C"&$C$70&":C"), INDIRECT("B"&$C$70&":B"), ">="&$A20, INDIRECT("B"&$C$70&":B"), "<"&$A21, INDIRECT("G"&$C$70&":G"), H$2) -> 0 | I20: =SUMIFS(INDIRECT("C"&$C$70&":C"), INDIRECT("B"&$C$70&":B"), ">="&$A20, INDIRECT("B"&$C$70&":B"), "<"&$A21, INDIRECT("G"&$C$70&":G"), I$2) -> 0 | J20: =SUMIFS(INDIRECT("C"&$C$70&":C"), INDIRECT("B"&$C$70&":B"), ">="&$A20, INDIRECT("B"&$C$70&":B"), "<"&$A21, INDIRECT("G"&$C$70&":G"), J$2) -> 6000 | K20: =SUMIFS(INDIRECT("C"&$C$70&":C"), INDIRECT("B"&$C$70&":B"), ">="&$A20, INDIRECT("B"&$C$70&":B"), "<"&$A21, INDIRECT("G"&$C$70&":G"), K$2) -> 0 | L20: =IFERROR(__xludf.DUMMYFUNCTION("TEXTJOIN("", "", TRUE, FILTER(INDIRECT(""U""&$C$70&"":U""), INDIRECT(""E""&$C$70&"":E"") = $F$1, INDIRECT(""B""&$C$70&"":B"") >= $A20, INDIRECT(""B""&$C$70&"":B"") <$A21))"),"$4470美債20年, $2520中信優息") -> $4470美債20年, $2520中信優息
A21: 46023 | B21: =SUMIFS(INDIRECT("C"&$C$70&":C"), INDIRECT("B"&$C$70&":B"), ">="&$A21, INDIRECT("B"&$C$70&":B"), "<"&$A22, INDIRECT("F"&$C$70&":F"), B$2) -> 107300 | C21: =SUMIFS(INDIRECT("C"&$C$70&":C"), INDIRECT("B"&$C$70&":B"), ">="&$A21, INDIRECT("B"&$C$70&":B"), "<"&$A22, INDIRECT("F"&$C$70&":F"), C$2) -> 0 | D21: =SUMIFS(INDIRECT("C"&$C$70&":C"), INDIRECT("B"&$C$70&":B"), ">="&$A21, INDIRECT("B"&$C$70&":B"), "<"&$A22, INDIRECT("F"&$C$70&":F"), D$2) -> 0 | E21: =IFERROR(__xludf.DUMMYFUNCTION("TEXTJOIN("", "", TRUE, FILTER(INDIRECT(""U""&$C$70&"":U""), INDIRECT(""E""&$C$70&"":E"") = $B$1, INDIRECT(""B""&$C$70&"":B"") >= $A21, INDIRECT(""B""&$C$70&"":B"") <$A22))"),"") | F21: =SUMIFS(INDIRECT("C"&$C$70&":C"), INDIRECT("B"&$C$70&":B"), ">="&$A21, INDIRECT("B"&$C$70&":B"), "<"&$A22, INDIRECT("G"&$C$70&":G"), F$2) -> 924 | G21: =SUMIFS(INDIRECT("C"&$C$70&":C"), INDIRECT("B"&$C$70&":B"), ">="&$A21, INDIRECT("B"&$C$70&":B"), "<"&$A22, INDIRECT("G"&$C$70&":G"), G$2) -> 0 | H21: =SUMIFS(INDIRECT("C"&$C$70&":C"), INDIRECT("B"&$C$70&":B"), ">="&$A21, INDIRECT("B"&$C$70&":B"), "<"&$A22, INDIRECT("G"&$C$70&":G"), H$2) -> 0 | I21: =SUMIFS(INDIRECT("C"&$C$70&":C"), INDIRECT("B"&$C$70&":B"), ">="&$A21, INDIRECT("B"&$C$70&":B"), "<"&$A22, INDIRECT("G"&$C$70&":G"), I$2) -> 0 | J21: =SUMIFS(INDIRECT("C"&$C$70&":C"), INDIRECT("B"&$C$70&":B"), ">="&$A21, INDIRECT("B"&$C$70&":B"), "<"&$A22, INDIRECT("G"&$C$70&":G"), J$2) -> 6000 | K21: =SUMIFS(INDIRECT("C"&$C$70&":C"), INDIRECT("B"&$C$70&":B"), ">="&$A21, INDIRECT("B"&$C$70&":B"), "<"&$A22, INDIRECT("G"&$C$70&":G"), K$2) -> 934600 | L21: =IFERROR(__xludf.DUMMYFUNCTION("TEXTJOIN("", "", TRUE, FILTER(INDIRECT(""U""&$C$70&"":U""), INDIRECT(""E""&$C$70&"":E"") = $F$1, INDIRECT(""B""&$C$70&"":B"") >= $A21, INDIRECT(""B""&$C$70&"":B"") <$A22))"),"$934600台銀人壽解約, $924中信優息") -> $934600台銀人壽解約, $924中信優息
A22: 46054 | B22: =SUMIFS(INDIRECT("C"&$C$70&":C"), INDIRECT("B"&$C$70&":B"), ">="&$A22, INDIRECT("B"&$C$70&":B"), "<"&$A23, INDIRECT("F"&$C$70&":F"), B$2) -> 106853 | C22: =SUMIFS(INDIRECT("C"&$C$70&":C"), INDIRECT("B"&$C$70&":B"), ">="&$A22, INDIRECT("B"&$C$70&":B"), "<"&$A23, INDIRECT("F"&$C$70&":F"), C$2) -> 0 | D22: =SUMIFS(INDIRECT("C"&$C$70&":C"), INDIRECT("B"&$C$70&":B"), ">="&$A22, INDIRECT("B"&$C$70&":B"), "<"&$A23, INDIRECT("F"&$C$70&":F"), D$2) -> 496487 | E22: =IFERROR(__xludf.DUMMYFUNCTION("TEXTJOIN("", "", TRUE, FILTER(INDIRECT(""U""&$C$70&"":U""), INDIRECT(""E""&$C$70&"":E"") = $B$1, INDIRECT(""B""&$C$70&"":B"") >= $A22, INDIRECT(""B""&$C$70&"":B"") <$A23))"),"$106853$447病假, $496487註1") -> $106853$447病假, $496487註1 | F22: =SUMIFS(INDIRECT("C"&$C$70&":C"), INDIRECT("B"&$C$70&":B"), ">="&$A22, INDIRECT("B"&$C$70&":B"), "<"&$A23, INDIRECT("G"&$C$70&":G"), F$2) -> 2200 | G22: =SUMIFS(INDIRECT("C"&$C$70&":C"), INDIRECT("B"&$C$70&":B"), ">="&$A22, INDIRECT("B"&$C$70&":B"), "<"&$A23, INDIRECT("G"&$C$70&":G"), G$2) -> 0 | H22: =SUMIFS(INDIRECT("C"&$C$70&":C"), INDIRECT("B"&$C$70&":B"), ">="&$A22, INDIRECT("B"&$C$70&":B"), "<"&$A23, INDIRECT("G"&$C$70&":G"), H$2) -> 0 | I22: =SUMIFS(INDIRECT("C"&$C$70&":C"), INDIRECT("B"&$C$70&":B"), ">="&$A22, INDIRECT("B"&$C$70&":B"), "<"&$A23, INDIRECT("G"&$C$70&":G"), I$2) -> 0 | J22: =SUMIFS(INDIRECT("C"&$C$70&":C"), INDIRECT("B"&$C$70&":B"), ">="&$A22, INDIRECT("B"&$C$70&":B"), "<"&$A23, INDIRECT("G"&$C$70&":G"), J$2) -> 6000 | K22: =SUMIFS(INDIRECT("C"&$C$70&":C"), INDIRECT("B"&$C$70&":B"), ">="&$A22, INDIRECT("B"&$C$70&":B"), "<"&$A23, INDIRECT("G"&$C$70&":G"), K$2) -> 0 | L22: =IFERROR(__xludf.DUMMYFUNCTION("TEXTJOIN("", "", TRUE, FILTER(INDIRECT(""U""&$C$70&"":U""), INDIRECT(""E""&$C$70&"":E"") = $F$1, INDIRECT(""B""&$C$70&"":B"") >= $A22, INDIRECT(""B""&$C$70&"":B"") <$A23))"),"$2200元大50") -> $2200元大50
A23: 46082 | B23: =SUMIFS(INDIRECT("C"&$C$70&":C"), INDIRECT("B"&$C$70&":B"), ">="&$A23, INDIRECT("B"&$C$70&":B"), "<"&$A24, INDIRECT("F"&$C$70&":F"), B$2) -> 107300 | C23: =SUMIFS(INDIRECT("C"&$C$70&":C"), INDIRECT("B"&$C$70&":B"), ">="&$A23, INDIRECT("B"&$C$70&":B"), "<"&$A24, INDIRECT("F"&$C$70&":F"), C$2) -> 0 | D23: =SUMIFS(INDIRECT("C"&$C$70&":C"), INDIRECT("B"&$C$70&":B"), ">="&$A23, INDIRECT("B"&$C$70&":B"), "<"&$A24, INDIRECT("F"&$C$70&":F"), D$2) -> 0 | E23: =IFERROR(__xludf.DUMMYFUNCTION("TEXTJOIN("", "", TRUE, FILTER(INDIRECT(""U""&$C$70&"":U""), INDIRECT(""E""&$C$70&"":E"") = $B$1, INDIRECT(""B""&$C$70&"":B"") >= $A23, INDIRECT(""B""&$C$70&"":B"") <$A24))"),"") | F23: =SUMIFS(INDIRECT("C"&$C$70&":C"), INDIRECT("B"&$C$70&":B"), ">="&$A23, INDIRECT("B"&$C$70&":B"), "<"&$A24, INDIRECT("G"&$C$70&":G"), F$2) -> 0 | G23: =SUMIFS(INDIRECT("C"&$C$70&":C"), INDIRECT("B"&$C$70&":B"), ">="&$A23, INDIRECT("B"&$C$70&":B"), "<"&$A24, INDIRECT("G"&$C$70&":G"), G$2) -> 0 | H23: =SUMIFS(INDIRECT("C"&$C$70&":C"), INDIRECT("B"&$C$70&":B"), ">="&$A23, INDIRECT("B"&$C$70&":B"), "<"&$A24, INDIRECT("G"&$C$70&":G"), H$2) -> 0 | I23: =SUMIFS(INDIRECT("C"&$C$70&":C"), INDIRECT("B"&$C$70&":B"), ">="&$A23, INDIRECT("B"&$C$70&":B"), "<"&$A24, INDIRECT("G"&$C$70&":G"), I$2) -> 0 | J23: =SUMIFS(INDIRECT("C"&$C$70&":C"), INDIRECT("B"&$C$70&":B"), ">="&$A23, INDIRECT("B"&$C$70&":B"), "<"&$A24, INDIRECT("G"&$C$70&":G"), J$2) -> 6000 | K23: =SUMIFS(INDIRECT("C"&$C$70&":C"), INDIRECT("B"&$C$70&":B"), ">="&$A23, INDIRECT("B"&$C$70&":B"), "<"&$A24, INDIRECT("G"&$C$70&":G"), K$2) -> 0 | L23: =IFERROR(__xludf.DUMMYFUNCTION("TEXTJOIN("", "", TRUE, FILTER(INDIRECT(""U""&$C$70&"":U""), INDIRECT(""E""&$C$70&"":E"") = $F$1, INDIRECT(""B""&$C$70&"":B"") >= $A23, INDIRECT(""B""&$C$70&"":B"") <$A24))"),"")
A24: 46113 | B24: =SUMIFS(INDIRECT("C"&$C$70&":C"), INDIRECT("B"&$C$70&":B"), ">="&$A24, INDIRECT("B"&$C$70&":B"), "<"&$A25, INDIRECT("F"&$C$70&":F"), B$2) -> 107300 | C24: =SUMIFS(INDIRECT("C"&$C$70&":C"), INDIRECT("B"&$C$70&":B"), ">="&$A24, INDIRECT("B"&$C$70&":B"), "<"&$A25, INDIRECT("F"&$C$70&":F"), C$2) -> 11927 | D24: =SUMIFS(INDIRECT("C"&$C$70&":C"), INDIRECT("B"&$C$70&":B"), ">="&$A24, INDIRECT("B"&$C$70&":B"), "<"&$A25, INDIRECT("F"&$C$70&":F"), D$2) -> 0 | E24: =IFERROR(__xludf.DUMMYFUNCTION("TEXTJOIN("", "", TRUE, FILTER(INDIRECT(""U""&$C$70&"":U""), INDIRECT(""E""&$C$70&"":E"") = $B$1, INDIRECT(""B""&$C$70&"":B"") >= $A24, INDIRECT(""B""&$C$70&"":B"") <$A25))"),"$5000其他加項(?)") -> $5000其他加項(?) | F24: =SUMIFS(INDIRECT("C"&$C$70&":C"), INDIRECT("B"&$C$70&":B"), ">="&$A24, INDIRECT("B"&$C$70&":B"), "<"&$A25, INDIRECT("G"&$C$70&":G"), F$2) -> 0 | G24: =SUMIFS(INDIRECT("C"&$C$70&":C"), INDIRECT("B"&$C$70&":B"), ">="&$A24, INDIRECT("B"&$C$70&":B"), "<"&$A25, INDIRECT("G"&$C$70&":G"), G$2) -> 0 | H24: =SUMIFS(INDIRECT("C"&$C$70&":C"), INDIRECT("B"&$C$70&":B"), ">="&$A24, INDIRECT("B"&$C$70&":B"), "<"&$A25, INDIRECT("G"&$C$70&":G"), H$2) -> 0 | I24: =SUMIFS(INDIRECT("C"&$C$70&":C"), INDIRECT("B"&$C$70&":B"), ">="&$A24, INDIRECT("B"&$C$70&":B"), "<"&$A25, INDIRECT("G"&$C$70&":G"), I$2) -> 0 | J24: =SUMIFS(INDIRECT("C"&$C$70&":C"), INDIRECT("B"&$C$70&":B"), ">="&$A24, INDIRECT("B"&$C$70&":B"), "<"&$A25, INDIRECT("G"&$C$70&":G"), J$2) -> 6000 | K24: =SUMIFS(INDIRECT("C"&$C$70&":C"), INDIRECT("B"&$C$70&":B"), ">="&$A24, INDIRECT("B"&$C$70&":B"), "<"&$A25, INDIRECT("G"&$C$70&":G"), K$2) -> 0 | L24: =IFERROR(__xludf.DUMMYFUNCTION("TEXTJOIN("", "", TRUE, FILTER(INDIRECT(""U""&$C$70&"":U""), INDIRECT(""E""&$C$70&"":E"") = $F$1, INDIRECT(""B""&$C$70&"":B"") >= $A24, INDIRECT(""B""&$C$70&"":B"") <$A25))"),"")
A25: 46143 | B25: =SUMIFS(INDIRECT("C"&$C$70&":C"), INDIRECT("B"&$C$70&":B"), ">="&$A25, INDIRECT("B"&$C$70&":B"), "<"&$A26, INDIRECT("F"&$C$70&":F"), B$2) -> 105512 | C25: =SUMIFS(INDIRECT("C"&$C$70&":C"), INDIRECT("B"&$C$70&":B"), ">="&$A25, INDIRECT("B"&$C$70&":B"), "<"&$A26, INDIRECT("F"&$C$70&":F"), C$2) -> 109991 | D25: =SUMIFS(INDIRECT("C"&$C$70&":C"), INDIRECT("B"&$C$70&":B"), ">="&$A25, INDIRECT("B"&$C$70&":B"), "<"&$A26, INDIRECT("F"&$C$70&":F"), D$2) -> 0 | E25: =IFERROR(__xludf.DUMMYFUNCTION("TEXTJOIN("", "", TRUE, FILTER(INDIRECT(""U""&$C$70&"":U""), INDIRECT(""E""&$C$70&"":E"") = $B$1, INDIRECT(""B""&$C$70&"":B"") >= $A25, INDIRECT(""B""&$C$70&"":B"") <$A26))"),"$105512 $1788請假, $107300家庭日獎金") -> $105512 $1788請假, $107300家庭日獎金 | F25: =SUMIFS(INDIRECT("C"&$C$70&":C"), INDIRECT("B"&$C$70&":B"), ">="&$A25, INDIRECT("B"&$C$70&":B"), "<"&$A26, INDIRECT("G"&$C$70&":G"), F$2) -> 0 | G25: =SUMIFS(INDIRECT("C"&$C$70&":C"), INDIRECT("B"&$C$70&":B"), ">="&$A25, INDIRECT("B"&$C$70&":B"), "<"&$A26, INDIRECT("G"&$C$70&":G"), G$2) -> 0 | H25: =SUMIFS(INDIRECT("C"&$C$70&":C"), INDIRECT("B"&$C$70&":B"), ">="&$A25, INDIRECT("B"&$C$70&":B"), "<"&$A26, INDIRECT("G"&$C$70&":G"), H$2) -> 0 | I25: =SUMIFS(INDIRECT("C"&$C$70&":C"), INDIRECT("B"&$C$70&":B"), ">="&$A25, INDIRECT("B"&$C$70&":B"), "<"&$A26, INDIRECT("G"&$C$70&":G"), I$2) -> 0 | J25: =SUMIFS(INDIRECT("C"&$C$70&":C"), INDIRECT("B"&$C$70&":B"), ">="&$A25, INDIRECT("B"&$C$70&":B"), "<"&$A26, INDIRECT("G"&$C$70&":G"), J$2) -> 6000 | K25: =SUMIFS(INDIRECT("C"&$C$70&":C"), INDIRECT("B"&$C$70&":B"), ">="&$A25, INDIRECT("B"&$C$70&":B"), "<"&$A26, INDIRECT("G"&$C$70&":G"), K$2) -> 0 | L25: =IFERROR(__xludf.DUMMYFUNCTION("TEXTJOIN("", "", TRUE, FILTER(INDIRECT(""U""&$C$70&"":U""), INDIRECT(""E""&$C$70&"":E"") = $F$1, INDIRECT(""B""&$C$70&"":B"") >= $A25, INDIRECT(""B""&$C$70&"":B"") <$A26))"),"")
A26: 46174 | B26: =SUMIFS(INDIRECT("C"&$C$70&":C"), INDIRECT("B"&$C$70&":B"), ">="&$A26, INDIRECT("B"&$C$70&":B"), "<"&$A27, INDIRECT("F"&$C$70&":F"), B$2) -> 110300 | C26: =SUMIFS(INDIRECT("C"&$C$70&":C"), INDIRECT("B"&$C$70&":B"), ">="&$A26, INDIRECT("B"&$C$70&":B"), "<"&$A27, INDIRECT("F"&$C$70&":F"), C$2) -> 0 | D26: =SUMIFS(INDIRECT("C"&$C$70&":C"), INDIRECT("B"&$C$70&":B"), ">="&$A26, INDIRECT("B"&$C$70&":B"), "<"&$A27, INDIRECT("F"&$C$70&":F"), D$2) -> 0 | E26: =IFERROR(__xludf.DUMMYFUNCTION("TEXTJOIN("", "", TRUE, FILTER(INDIRECT(""U""&$C$70&"":U""), INDIRECT(""E""&$C$70&"":E"") = $B$1, INDIRECT(""B""&$C$70&"":B"") >= $A26, INDIRECT(""B""&$C$70&"":B"") <$A27))"),"") | F26: =SUMIFS(INDIRECT("C"&$C$70&":C"), INDIRECT("B"&$C$70&":B"), ">="&$A26, INDIRECT("B"&$C$70&":B"), "<"&$A27, INDIRECT("G"&$C$70&":G"), F$2) -> 2800 | G26: =SUMIFS(INDIRECT("C"&$C$70&":C"), INDIRECT("B"&$C$70&":B"), ">="&$A26, INDIRECT("B"&$C$70&":B"), "<"&$A27, INDIRECT("G"&$C$70&":G"), G$2) -> 0 | H26: =SUMIFS(INDIRECT("C"&$C$70&":C"), INDIRECT("B"&$C$70&":B"), ">="&$A26, INDIRECT("B"&$C$70&":B"), "<"&$A27, INDIRECT("G"&$C$70&":G"), H$2) -> 0 | I26: =SUMIFS(INDIRECT("C"&$C$70&":C"), INDIRECT("B"&$C$70&":B"), ">="&$A26, INDIRECT("B"&$C$70&":B"), "<"&$A27, INDIRECT("G"&$C$70&":G"), I$2) -> 0 | J26: =SUMIFS(INDIRECT("C"&$C$70&":C"), INDIRECT("B"&$C$70&":B"), ">="&$A26, INDIRECT("B"&$C$70&":B"), "<"&$A27, INDIRECT("G"&$C$70&":G"), J$2) -> 6000 | K26: =SUMIFS(INDIRECT("C"&$C$70&":C"), INDIRECT("B"&$C$70&":B"), ">="&$A26, INDIRECT("B"&$C$70&":B"), "<"&$A27, INDIRECT("G"&$C$70&":G"), K$2) -> 0 | L26: =IFERROR(__xludf.DUMMYFUNCTION("TEXTJOIN("", "", TRUE, FILTER(INDIRECT(""U""&$C$70&"":U""), INDIRECT(""E""&$C$70&"":E"") = $F$1, INDIRECT(""B""&$C$70&"":B"") >= $A26, INDIRECT(""B""&$C$70&"":B"") <$A27))"),"$2800華通") -> $2800華通
A27: 46204 | B27: =SUMIFS(INDIRECT("C"&$C$70&":C"), INDIRECT("B"&$C$70&":B"), ">="&$A27, INDIRECT("B"&$C$70&":B"), "<"&$A28, INDIRECT("F"&$C$70&":F"), B$2) -> 110300 | C27: =SUMIFS(INDIRECT("C"&$C$70&":C"), INDIRECT("B"&$C$70&":B"), ">="&$A27, INDIRECT("B"&$C$70&":B"), "<"&$A28, INDIRECT("F"&$C$70&":F"), C$2) -> 0 | D27: =SUMIFS(INDIRECT("C"&$C$70&":C"), INDIRECT("B"&$C$70&":B"), ">="&$A27, INDIRECT("B"&$C$70&":B"), "<"&$A28, INDIRECT("F"&$C$70&":F"), D$2) -> 0 | E27: =IFERROR(__xludf.DUMMYFUNCTION("TEXTJOIN("", "", TRUE, FILTER(INDIRECT(""U""&$C$70&"":U""), INDIRECT(""E""&$C$70&"":E"") = $B$1, INDIRECT(""B""&$C$70&"":B"") >= $A27, INDIRECT(""B""&$C$70&"":B"") <$A28))"),"") | F27: =SUMIFS(INDIRECT("C"&$C$70&":C"), INDIRECT("B"&$C$70&":B"), ">="&$A27, INDIRECT("B"&$C$70&":B"), "<"&$A28, INDIRECT("G"&$C$70&":G"), F$2) -> 0 | G27: =SUMIFS(INDIRECT("C"&$C$70&":C"), INDIRECT("B"&$C$70&":B"), ">="&$A27, INDIRECT("B"&$C$70&":B"), "<"&$A28, INDIRECT("G"&$C$70&":G"), G$2) -> 0 | H27: =SUMIFS(INDIRECT("C"&$C$70&":C"), INDIRECT("B"&$C$70&":B"), ">="&$A27, INDIRECT("B"&$C$70&":B"), "<"&$A28, INDIRECT("G"&$C$70&":G"), H$2) -> 0 | I27: =SUMIFS(INDIRECT("C"&$C$70&":C"), INDIRECT("B"&$C$70&":B"), ">="&$A27, INDIRECT("B"&$C$70&":B"), "<"&$A28, INDIRECT("G"&$C$70&":G"), I$2) -> 0 | J27: =SUMIFS(INDIRECT("C"&$C$70&":C"), INDIRECT("B"&$C$70&":B"), ">="&$A27, INDIRECT("B"&$C$70&":B"), "<"&$A28, INDIRECT("G"&$C$70&":G"), J$2) -> 6000 | K27: =SUMIFS(INDIRECT("C"&$C$70&":C"), INDIRECT("B"&$C$70&":B"), ">="&$A27, INDIRECT("B"&$C$70&":B"), "<"&$A28, INDIRECT("G"&$C$70&":G"), K$2) -> 0 | L27: =IFERROR(__xludf.DUMMYFUNCTION("TEXTJOIN("", "", TRUE, FILTER(INDIRECT(""U""&$C$70&"":U""), INDIRECT(""E""&$C$70&"":E"") = $F$1, INDIRECT(""B""&$C$70&"":B"") >= $A27, INDIRECT(""B""&$C$70&"":B"") <$A28))"),"")
A28: 46235 | B28: =SUMIFS(INDIRECT("C"&$C$70&":C"), INDIRECT("B"&$C$70&":B"), ">="&$A28, INDIRECT("B"&$C$70&":B"), "<"&$A29, INDIRECT("F"&$C$70&":F"), B$2) -> 0 | C28: =SUMIFS(INDIRECT("C"&$C$70&":C"), INDIRECT("B"&$C$70&":B"), ">="&$A28, INDIRECT("B"&$C$70&":B"), "<"&$A29, INDIRECT("F"&$C$70&":F"), C$2) -> 0 | D28: =SUMIFS(INDIRECT("C"&$C$70&":C"), INDIRECT("B"&$C$70&":B"), ">="&$A28, INDIRECT("B"&$C$70&":B"), "<"&$A29, INDIRECT("F"&$C$70&":F"), D$2) -> 0 | E28: =IFERROR(__xludf.DUMMYFUNCTION("TEXTJOIN("", "", TRUE, FILTER(INDIRECT(""U""&$C$70&"":U""), INDIRECT(""E""&$C$70&"":E"") = $B$1, INDIRECT(""B""&$C$70&"":B"") >= $A28, INDIRECT(""B""&$C$70&"":B"") <$A29))"),"#N/A") -> #N/A | F28: =SUMIFS(INDIRECT("C"&$C$70&":C"), INDIRECT("B"&$C$70&":B"), ">="&$A28, INDIRECT("B"&$C$70&":B"), "<"&$A29, INDIRECT("G"&$C$70&":G"), F$2) -> 0 | G28: =SUMIFS(INDIRECT("C"&$C$70&":C"), INDIRECT("B"&$C$70&":B"), ">="&$A28, INDIRECT("B"&$C$70&":B"), "<"&$A29, INDIRECT("G"&$C$70&":G"), G$2) -> 0 | H28: =SUMIFS(INDIRECT("C"&$C$70&":C"), INDIRECT("B"&$C$70&":B"), ">="&$A28, INDIRECT("B"&$C$70&":B"), "<"&$A29, INDIRECT("G"&$C$70&":G"), H$2) -> 0 | I28: =SUMIFS(INDIRECT("C"&$C$70&":C"), INDIRECT("B"&$C$70&":B"), ">="&$A28, INDIRECT("B"&$C$70&":B"), "<"&$A29, INDIRECT("G"&$C$70&":G"), I$2) -> 0 | J28: =SUMIFS(INDIRECT("C"&$C$70&":C"), INDIRECT("B"&$C$70&":B"), ">="&$A28, INDIRECT("B"&$C$70&":B"), "<"&$A29, INDIRECT("G"&$C$70&":G"), J$2) -> 0 | K28: =SUMIFS(INDIRECT("C"&$C$70&":C"), INDIRECT("B"&$C$70&":B"), ">="&$A28, INDIRECT("B"&$C$70&":B"), "<"&$A29, INDIRECT("G"&$C$70&":G"), K$2) -> 0 | L28: =IFERROR(__xludf.DUMMYFUNCTION("TEXTJOIN("", "", TRUE, FILTER(INDIRECT(""U""&$C$70&"":U""), INDIRECT(""E""&$C$70&"":E"") = $F$1, INDIRECT(""B""&$C$70&"":B"") >= $A28, INDIRECT(""B""&$C$70&"":B"") <$A29))"),"#N/A") -> #N/A
A29: 46266 | B29: =SUMIFS(INDIRECT("C"&$C$70&":C"), INDIRECT("B"&$C$70&":B"), ">="&$A29, INDIRECT("B"&$C$70&":B"), "<"&$A30, INDIRECT("F"&$C$70&":F"), B$2) -> 0 | C29: =SUMIFS(INDIRECT("C"&$C$70&":C"), INDIRECT("B"&$C$70&":B"), ">="&$A29, INDIRECT("B"&$C$70&":B"), "<"&$A30, INDIRECT("F"&$C$70&":F"), C$2) -> 0 | D29: =SUMIFS(INDIRECT("C"&$C$70&":C"), INDIRECT("B"&$C$70&":B"), ">="&$A29, INDIRECT("B"&$C$70&":B"), "<"&$A30, INDIRECT("F"&$C$70&":F"), D$2) -> 0 | E29: =IFERROR(__xludf.DUMMYFUNCTION("TEXTJOIN("", "", TRUE, FILTER(INDIRECT(""U""&$C$70&"":U""), INDIRECT(""E""&$C$70&"":E"") = $B$1, INDIRECT(""B""&$C$70&"":B"") >= $A29, INDIRECT(""B""&$C$70&"":B"") <$A30))"),"#N/A") -> #N/A | F29: =SUMIFS(INDIRECT("C"&$C$70&":C"), INDIRECT("B"&$C$70&":B"), ">="&$A29, INDIRECT("B"&$C$70&":B"), "<"&$A30, INDIRECT("G"&$C$70&":G"), F$2) -> 0 | G29: =SUMIFS(INDIRECT("C"&$C$70&":C"), INDIRECT("B"&$C$70&":B"), ">="&$A29, INDIRECT("B"&$C$70&":B"), "<"&$A30, INDIRECT("G"&$C$70&":G"), G$2) -> 0 | H29: =SUMIFS(INDIRECT("C"&$C$70&":C"), INDIRECT("B"&$C$70&":B"), ">="&$A29, INDIRECT("B"&$C$70&":B"), "<"&$A30, INDIRECT("G"&$C$70&":G"), H$2) -> 0 | I29: =SUMIFS(INDIRECT("C"&$C$70&":C"), INDIRECT("B"&$C$70&":B"), ">="&$A29, INDIRECT("B"&$C$70&":B"), "<"&$A30, INDIRECT("G"&$C$70&":G"), I$2) -> 0 | J29: =SUMIFS(INDIRECT("C"&$C$70&":C"), INDIRECT("B"&$C$70&":B"), ">="&$A29, INDIRECT("B"&$C$70&":B"), "<"&$A30, INDIRECT("G"&$C$70&":G"), J$2) -> 0 | K29: =SUMIFS(INDIRECT("C"&$C$70&":C"), INDIRECT("B"&$C$70&":B"), ">="&$A29, INDIRECT("B"&$C$70&":B"), "<"&$A30, INDIRECT("G"&$C$70&":G"), K$2) -> 0 | L29: =IFERROR(__xludf.DUMMYFUNCTION("TEXTJOIN("", "", TRUE, FILTER(INDIRECT(""U""&$C$70&"":U""), INDIRECT(""E""&$C$70&"":E"") = $F$1, INDIRECT(""B""&$C$70&"":B"") >= $A29, INDIRECT(""B""&$C$70&"":B"") <$A30))"),"#N/A") -> #N/A
A30: 46296 | B30: =SUMIFS(INDIRECT("C"&$C$70&":C"), INDIRECT("B"&$C$70&":B"), ">="&$A30, INDIRECT("B"&$C$70&":B"), "<"&$A31, INDIRECT("F"&$C$70&":F"), B$2) -> 0 | C30: =SUMIFS(INDIRECT("C"&$C$70&":C"), INDIRECT("B"&$C$70&":B"), ">="&$A30, INDIRECT("B"&$C$70&":B"), "<"&$A31, INDIRECT("F"&$C$70&":F"), C$2) -> 0 | D30: =SUMIFS(INDIRECT("C"&$C$70&":C"), INDIRECT("B"&$C$70&":B"), ">="&$A30, INDIRECT("B"&$C$70&":B"), "<"&$A31, INDIRECT("F"&$C$70&":F"), D$2) -> 0 | E30: =IFERROR(__xludf.DUMMYFUNCTION("TEXTJOIN("", "", TRUE, FILTER(INDIRECT(""U""&$C$70&"":U""), INDIRECT(""E""&$C$70&"":E"") = $B$1, INDIRECT(""B""&$C$70&"":B"") >= $A30, INDIRECT(""B""&$C$70&"":B"") <$A31))"),"#N/A") -> #N/A | F30: =SUMIFS(INDIRECT("C"&$C$70&":C"), INDIRECT("B"&$C$70&":B"), ">="&$A30, INDIRECT("B"&$C$70&":B"), "<"&$A31, INDIRECT("G"&$C$70&":G"), F$2) -> 0 | G30: =SUMIFS(INDIRECT("C"&$C$70&":C"), INDIRECT("B"&$C$70&":B"), ">="&$A30, INDIRECT("B"&$C$70&":B"), "<"&$A31, INDIRECT("G"&$C$70&":G"), G$2) -> 0 | H30: =SUMIFS(INDIRECT("C"&$C$70&":C"), INDIRECT("B"&$C$70&":B"), ">="&$A30, INDIRECT("B"&$C$70&":B"), "<"&$A31, INDIRECT("G"&$C$70&":G"), H$2) -> 0 | I30: =SUMIFS(INDIRECT("C"&$C$70&":C"), INDIRECT("B"&$C$70&":B"), ">="&$A30, INDIRECT("B"&$C$70&":B"), "<"&$A31, INDIRECT("G"&$C$70&":G"), I$2) -> 0 | J30: =SUMIFS(INDIRECT("C"&$C$70&":C"), INDIRECT("B"&$C$70&":B"), ">="&$A30, INDIRECT("B"&$C$70&":B"), "<"&$A31, INDIRECT("G"&$C$70&":G"), J$2) -> 0 | K30: =SUMIFS(INDIRECT("C"&$C$70&":C"), INDIRECT("B"&$C$70&":B"), ">="&$A30, INDIRECT("B"&$C$70&":B"), "<"&$A31, INDIRECT("G"&$C$70&":G"), K$2) -> 0 | L30: =IFERROR(__xludf.DUMMYFUNCTION("TEXTJOIN("", "", TRUE, FILTER(INDIRECT(""U""&$C$70&"":U""), INDIRECT(""E""&$C$70&"":E"") = $F$1, INDIRECT(""B""&$C$70&"":B"") >= $A30, INDIRECT(""B""&$C$70&"":B"") <$A31))"),"#N/A") -> #N/A
A31: 46327 | B31: =SUMIFS(INDIRECT("C"&$C$70&":C"), INDIRECT("B"&$C$70&":B"), ">="&$A31, INDIRECT("B"&$C$70&":B"), "<"&$A32, INDIRECT("F"&$C$70&":F"), B$2) -> 0 | C31: =SUMIFS(INDIRECT("C"&$C$70&":C"), INDIRECT("B"&$C$70&":B"), ">="&$A31, INDIRECT("B"&$C$70&":B"), "<"&$A32, INDIRECT("F"&$C$70&":F"), C$2) -> 0 | D31: =SUMIFS(INDIRECT("C"&$C$70&":C"), INDIRECT("B"&$C$70&":B"), ">="&$A31, INDIRECT("B"&$C$70&":B"), "<"&$A32, INDIRECT("F"&$C$70&":F"), D$2) -> 0 | E31: =IFERROR(__xludf.DUMMYFUNCTION("TEXTJOIN("", "", TRUE, FILTER(INDIRECT(""U""&$C$70&"":U""), INDIRECT(""E""&$C$70&"":E"") = $B$1, INDIRECT(""B""&$C$70&"":B"") >= $A31, INDIRECT(""B""&$C$70&"":B"") <$A32))"),"#N/A") -> #N/A | F31: =SUMIFS(INDIRECT("C"&$C$70&":C"), INDIRECT("B"&$C$70&":B"), ">="&$A31, INDIRECT("B"&$C$70&":B"), "<"&$A32, INDIRECT("G"&$C$70&":G"), F$2) -> 0 | G31: =SUMIFS(INDIRECT("C"&$C$70&":C"), INDIRECT("B"&$C$70&":B"), ">="&$A31, INDIRECT("B"&$C$70&":B"), "<"&$A32, INDIRECT("G"&$C$70&":G"), G$2) -> 0 | H31: =SUMIFS(INDIRECT("C"&$C$70&":C"), INDIRECT("B"&$C$70&":B"), ">="&$A31, INDIRECT("B"&$C$70&":B"), "<"&$A32, INDIRECT("G"&$C$70&":G"), H$2) -> 0 | I31: =SUMIFS(INDIRECT("C"&$C$70&":C"), INDIRECT("B"&$C$70&":B"), ">="&$A31, INDIRECT("B"&$C$70&":B"), "<"&$A32, INDIRECT("G"&$C$70&":G"), I$2) -> 0 | J31: =SUMIFS(INDIRECT("C"&$C$70&":C"), INDIRECT("B"&$C$70&":B"), ">="&$A31, INDIRECT("B"&$C$70&":B"), "<"&$A32, INDIRECT("G"&$C$70&":G"), J$2) -> 0 | K31: =SUMIFS(INDIRECT("C"&$C$70&":C"), INDIRECT("B"&$C$70&":B"), ">="&$A31, INDIRECT("B"&$C$70&":B"), "<"&$A32, INDIRECT("G"&$C$70&":G"), K$2) -> 0 | L31: =IFERROR(__xludf.DUMMYFUNCTION("TEXTJOIN("", "", TRUE, FILTER(INDIRECT(""U""&$C$70&"":U""), INDIRECT(""E""&$C$70&"":E"") = $F$1, INDIRECT(""B""&$C$70&"":B"") >= $A31, INDIRECT(""B""&$C$70&"":B"") <$A32))"),"#N/A") -> #N/A
A32: 46357 | B32: =SUMIFS(INDIRECT("C"&$C$70&":C"), INDIRECT("B"&$C$70&":B"), ">="&$A32, INDIRECT("B"&$C$70&":B"), "<"&$A33, INDIRECT("F"&$C$70&":F"), B$2) -> 0 | C32: =SUMIFS(INDIRECT("C"&$C$70&":C"), INDIRECT("B"&$C$70&":B"), ">="&$A32, INDIRECT("B"&$C$70&":B"), "<"&$A33, INDIRECT("F"&$C$70&":F"), C$2) -> 0 | D32: =SUMIFS(INDIRECT("C"&$C$70&":C"), INDIRECT("B"&$C$70&":B"), ">="&$A32, INDIRECT("B"&$C$70&":B"), "<"&$A33, INDIRECT("F"&$C$70&":F"), D$2) -> 0 | E32: =IFERROR(__xludf.DUMMYFUNCTION("TEXTJOIN("", "", TRUE, FILTER(INDIRECT(""U""&$C$70&"":U""), INDIRECT(""E""&$C$70&"":E"") = $B$1, INDIRECT(""B""&$C$70&"":B"") >= $A32, INDIRECT(""B""&$C$70&"":B"") <$A33))"),"#N/A") -> #N/A | F32: =SUMIFS(INDIRECT("C"&$C$70&":C"), INDIRECT("B"&$C$70&":B"), ">="&$A32, INDIRECT("B"&$C$70&":B"), "<"&$A33, INDIRECT("G"&$C$70&":G"), F$2) -> 0 | G32: =SUMIFS(INDIRECT("C"&$C$70&":C"), INDIRECT("B"&$C$70&":B"), ">="&$A32, INDIRECT("B"&$C$70&":B"), "<"&$A33, INDIRECT("G"&$C$70&":G"), G$2) -> 0 | H32: =SUMIFS(INDIRECT("C"&$C$70&":C"), INDIRECT("B"&$C$70&":B"), ">="&$A32, INDIRECT("B"&$C$70&":B"), "<"&$A33, INDIRECT("G"&$C$70&":G"), H$2) -> 0 | I32: =SUMIFS(INDIRECT("C"&$C$70&":C"), INDIRECT("B"&$C$70&":B"), ">="&$A32, INDIRECT("B"&$C$70&":B"), "<"&$A33, INDIRECT("G"&$C$70&":G"), I$2) -> 0 | J32: =SUMIFS(INDIRECT("C"&$C$70&":C"), INDIRECT("B"&$C$70&":B"), ">="&$A32, INDIRECT("B"&$C$70&":B"), "<"&$A33, INDIRECT("G"&$C$70&":G"), J$2) -> 0 | K32: =SUMIFS(INDIRECT("C"&$C$70&":C"), INDIRECT("B"&$C$70&":B"), ">="&$A32, INDIRECT("B"&$C$70&":B"), "<"&$A33, INDIRECT("G"&$C$70&":G"), K$2) -> 0 | L32: =IFERROR(__xludf.DUMMYFUNCTION("TEXTJOIN("", "", TRUE, FILTER(INDIRECT(""U""&$C$70&"":U""), INDIRECT(""E""&$C$70&"":E"") = $F$1, INDIRECT(""B""&$C$70&"":B"") >= $A32, INDIRECT(""B""&$C$70&"":B"") <$A33))"),"#N/A") -> #N/A
B34: 生活 | D34: 稅金/利息 | F34: 房屋 | K34: 汽機車 | Q34: 其他 | S34: 備註
